[META]
version=2.0
spawnOnBlockType=1,2,3,12
spawnSunlight=True
spawnDarkness=True
spawnWater=True
spawnLava=False
underFill=True
randomRotation=True
dig=True
tree=True
branch=False
needsFoundation=True
rarity=999
collisionPercentage=70
spawnElevationMin=0
spawnElevationMax=200
spawnInBiome=All
[DATA]
-19,15,0:17
-18,14,0:17
-18,15,0:17
-18,16,0:17
-17,12,0:17
-17,13,0:17
-17,14,0:17
-17,15,0:17
-16,10,0:17
-16,11,0:17
-16,12,0:17
-16,13,0:17
-16,14,0:17
-15,9,0:17
-15,10,0:17
-15,11,0:17
-15,12,0:17
-14,8,0:17
-14,9,0:17
-14,10,0:17
-14,11,0:17
-14,12,0:17
-13,-19,0:17
-13,-18,0:17
-13,5,0:17
-13,6,0:17
-13,7,0:17
-13,8,0:17
-13,9,0:17
-13,10,0:17
-13,11,0:17
-12,-20,0:17
-12,-19,0:17
-12,-18,0:17
-12,-17,0:17
-12,2,0:17
-12,4,0:17
-12,5,0:17
-12,6,0:17
-12,7,0:17
-12,8,0:17
-12,9,0:17
-12,10,0:17
-11,-19,0:17
-11,-18,0:17
-11,-17,0:17
-11,-16,0:17
-11,-15,0:17
-11,-14,0:17
-11,0,0:17
-11,1,0:17
-11,2,0:17
-11,3,0:17
-11,4,0:17
-11,5,0:17
-11,6,0:17
-11,7,0:17
-11,8,0:17
-11,9,0:17
-10,-18,0:17
-10,-17,0:17
-10,-16,0:17
-10,-15,0:17
-10,-14,0:17
-10,-13,0:17
-10,-9,0:17
-10,-8,0:17
-10,-4,0:17
-10,0,0:17
-10,1,0:17
-10,2,0:17
-10,3,0:17
-10,4,0:17
-10,5,0:17
-10,6,0:17
-10,7,0:17
-10,8,0:17
-9,-16,0:17
-9,-15,0:17
-9,-14,0:17
-9,-13,0:17
-9,-12,0:17
-9,-11,0:17
-9,-10,0:17
-9,-9,0:17
-9,-8,0:17
-9,-7,0:17
-9,-5,0:17
-9,-4,0:17
-9,-3,0:17
-9,0,0:17
-9,1,0:17
-9,2,0:17
-9,3,0:17
-9,4,0:17
-9,5,0:17
-9,6,0:17
-9,7,0:17
-9,8,0:17
-8,-14,0:17
-8,-13,0:17
-8,-12,0:17
-8,-11,0:17
-8,-10,0:17
-8,-9,0:17
-8,-8,0:17
-8,-7,0:17
-8,-6,0:17
-8,-5,0:17
-8,-4,0:17
-8,-3,0:17
-8,-2,0:17
-8,-1,0:17
-8,0,0:17
-8,1,0:17
-8,2,0:17
-8,3,0:17
-8,4,0:17
-8,5,0:17
-8,6,0:17
-8,7,0:17
-7,-14,0:17
-7,-13,0:17
-7,-12,0:17
-7,-11,0:17
-7,-10,0:17
-7,-9,0:17
-7,-8,0:17
-7,-7,0:17
-7,-6,0:17
-7,-5,0:17
-7,-4,0:17
-7,-3,0:17
-7,-2,0:17
-7,-1,0:17
-7,0,0:17
-7,1,0:17
-7,2,0:17
-7,3,0:17
-7,4,0:17
-7,5,0:17
-7,6,0:17
-6,-13,0:17
-6,-12,0:17
-6,-11,0:17
-6,-10,0:17
-6,-9,0:17
-6,-8,0:17
-6,-7,0:17
-6,-6,0:17
-6,-5,0:17
-6,-4,0:17
-6,-3,0:17
-6,-2,0:17
-6,-1,0:17
-6,0,0:17
-6,1,0:17
-6,2,0:17
-6,3,0:17
-6,4,0:17
-6,5,0:17
-5,-10,0:17
-5,-9,0:17
-5,-8,0:17
-5,-7,0:17
-5,-6,0:17
-5,-5,0:17
-5,-4,0:17
-5,-3,0:17
-5,-2,0:17
-5,-1,0:17
-5,0,0:17
-5,1,0:17
-5,2,0:17
-5,3,0:17
-5,4,0:17
-5,5,0:17
-4,-9,0:17
-4,-8,0:17
-4,-7,0:17
-4,-6,0:17
-4,-5,0:17
-4,-4,0:17
-4,-3,0:17
-4,-2,0:17
-4,-1,0:17
-4,0,0:17
-4,1,0:17
-4,2,0:17
-4,3,0:17
-3,-7,0:17
-3,-6,0:17
-3,-5,0:17
-3,-4,0:17
-3,-3,0:17
-3,-2,0:17
-3,-1,0:17
-3,0,0:17
-3,1,0:17
-3,2,0:17
-3,3,0:17
-2,-6,0:17
-2,-5,0:17
-2,-4,0:17
-2,-3,0:17
-2,-2,0:17
-2,-1,0:17
-2,0,0:17
-2,1,0:17
-2,2,0:17
-2,3,0:17
-2,4,0:17
-1,-8,0:17
-1,-7,0:17
-1,-6,0:17
-1,-5,0:17
-1,-4,0:17
-1,-3,0:17
-1,-2,0:17
-1,-1,0:17
-1,0,0:17
-1,1,0:17
-1,2,0:17
-1,3,0:17
-1,4,0:17
0,-8,0:17
0,-7,0:17
0,-6,0:17
0,-5,0:17
0,-4,0:17
0,-3,0:17
0,-2,0:17
0,-1,0:17
0,0,0:17
0,1,0:17
0,2,0:17
0,3,0:17
0,4,0:17
1,-8,0:17
1,-7,0:17
1,-6,0:17
1,-5,0:17
1,-4,0:17
1,-3,0:17
1,-2,0:17
1,-1,0:17
1,0,0:17
1,1,0:17
1,2,0:17
1,3,0:17
1,4,0:17
1,5,0:17
1,6,0:17
2,-8,0:17
2,-7,0:17
2,-6,0:17
2,-3,0:17
2,-2,0:17
2,-1,0:17
2,0,0:17
2,1,0:17
2,2,0:17
2,3,0:17
2,4,0:17
2,5,0:17
2,6,0:17
2,7,0:17
3,-1,0:17
3,0,0:17
3,1,0:17
3,2,0:17
3,3,0:17
3,4,0:17
3,5,0:17
3,6,0:17
3,7,0:17
4,-8,0:17
4,0,0:17
4,1,0:17
4,3,0:17
4,4,0:17
4,5,0:17
4,6,0:17
4,7,0:17
5,-10,0:17
5,4,0:17
5,5,0:17
5,6,0:17
5,7,0:17
5,8,0:17
6,5,0:17
6,6,0:17
6,7,0:17
6,8,0:17
6,9,0:17
7,6,0:17
7,7,0:17
7,8,0:17
7,9,0:17
7,10,0:17
7,11,0:17
8,6,0:17
8,7,0:17
8,8,0:17
8,9,0:17
8,10,0:17
8,11,0:17
9,9,0:17
9,10,0:17
9,11,0:17
9,12,0:17
10,10,0:17
10,11,0:17
25,18,0:17
25,20,0:17
26,15,0:17
-18,15,1:17
-17,12,1:17
-17,14,1:17
-16,11,1:17
-16,12,1:17
-16,13,1:17
-15,9,1:17
-15,10,1:17
-15,11,1:17
-15,12,1:17
-14,9,1:17
-14,10,1:17
-14,11,1:17
-13,6,1:17
-13,7,1:17
-13,8,1:17
-13,9,1:17
-13,10,1:17
-13,11,1:17
-12,-19,1:17
-12,-18,1:17
-12,2,1:17
-12,5,1:17
-12,6,1:17
-12,7,1:17
-12,8,1:17
-12,9,1:17
-11,-18,1:17
-11,-17,1:17
-11,-16,1:17
-11,-15,1:17
-11,0,1:17
-11,1,1:17
-11,2,1:17
-11,3,1:17
-11,4,1:17
-11,5,1:17
-11,6,1:17
-11,7,1:17
-11,8,1:17
-11,9,1:17
-10,-17,1:17
-10,-16,1:17
-10,-15,1:17
-10,-14,1:17
-10,-9,1:17
-10,-8,1:17
-10,-4,1:17
-10,0,1:17
-10,1,1:17
-10,2,1:17
-10,3,1:17
-10,4,1:17
-10,5,1:17
-10,6,1:17
-10,7,1:17
-9,-16,1:17
-9,-15,1:17
-9,-14,1:17
-9,-13,1:17
-9,-12,1:17
-9,-11,1:17
-9,-10,1:17
-9,-9,1:17
-9,-8,1:17
-9,-7,1:17
-9,-5,1:17
-9,-4,1:17
-9,-3,1:17
-9,0,1:17
-9,1,1:17
-9,2,1:17
-9,3,1:17
-9,4,1:17
-9,5,1:17
-9,6,1:17
-9,7,1:17
-8,-14,1:17
-8,-13,1:17
-8,-12,1:17
-8,-11,1:17
-8,-10,1:17
-8,-9,1:17
-8,-8,1:17
-8,-7,1:17
-8,-6,1:17
-8,-5,1:17
-8,-4,1:17
-8,-3,1:17
-8,-2,1:17
-8,-1,1:17
-8,0,1:17
-8,1,1:17
-8,2,1:17
-8,3,1:17
-8,4,1:17
-8,5,1:17
-8,6,1:17
-7,-14,1:17
-7,-13,1:17
-7,-12,1:17
-7,-11,1:17
-7,-10,1:17
-7,-9,1:17
-7,-8,1:17
-7,-7,1:17
-7,-6,1:17
-7,-5,1:17
-7,-4,1:17
-7,-3,1:17
-7,-2,1:17
-7,-1,1:17
-7,0,1:17
-7,1,1:17
-7,2,1:17
-7,3,1:17
-7,4,1:17
-7,5,1:17
-6,-13,1:17
-6,-12,1:17
-6,-11,1:17
-6,-10,1:17
-6,-9,1:17
-6,-8,1:17
-6,-7,1:17
-6,-6,1:17
-6,-5,1:17
-6,-4,1:17
-6,-3,1:17
-6,-2,1:17
-6,-1,1:17
-6,0,1:17
-6,1,1:17
-6,2,1:17
-6,3,1:17
-6,4,1:17
-6,5,1:17
-5,-10,1:17
-5,-9,1:17
-5,-8,1:17
-5,-7,1:17
-5,-6,1:17
-5,-5,1:17
-5,-4,1:17
-5,-3,1:17
-5,-2,1:17
-5,-1,1:17
-5,0,1:17
-5,1,1:17
-5,2,1:17
-5,3,1:17
-5,4,1:17
-5,5,1:17
-4,-9,1:17
-4,-8,1:17
-4,-7,1:17
-4,-6,1:17
-4,-5,1:17
-4,-4,1:17
-4,-3,1:17
-4,-2,1:17
-4,-1,1:17
-4,0,1:17
-4,1,1:17
-4,2,1:17
-4,3,1:17
-3,-7,1:17
-3,-6,1:17
-3,-5,1:17
-3,-4,1:17
-3,-3,1:17
-3,-2,1:17
-3,-1,1:17
-3,0,1:17
-3,1,1:17
-3,2,1:17
-3,3,1:17
-2,-6,1:17
-2,-5,1:17
-2,-4,1:17
-2,-3,1:17
-2,-2,1:17
-2,-1,1:17
-2,0,1:17
-2,1,1:17
-2,2,1:17
-2,3,1:17
-2,4,1:17
-1,-8,1:17
-1,-7,1:17
-1,-6,1:17
-1,-5,1:17
-1,-4,1:17
-1,-3,1:17
-1,-2,1:17
-1,-1,1:17
-1,0,1:17
-1,1,1:17
-1,2,1:17
-1,3,1:17
-1,4,1:17
0,-8,1:17
0,-7,1:17
0,-6,1:17
0,-5,1:17
0,-4,1:17
0,-3,1:17
0,-2,1:17
0,-1,1:17
0,0,1:17
0,1,1:17
0,2,1:17
0,3,1:17
0,4,1:17
1,-8,1:17
1,-7,1:17
1,-6,1:17
1,-5,1:17
1,-4,1:17
1,-3,1:17
1,-2,1:17
1,-1,1:17
1,0,1:17
1,1,1:17
1,2,1:17
1,3,1:17
1,4,1:17
1,5,1:17
1,6,1:17
2,-8,1:17
2,-7,1:17
2,-6,1:17
2,-3,1:17
2,-2,1:17
2,-1,1:17
2,0,1:17
2,1,1:17
2,2,1:17
2,3,1:17
2,4,1:17
2,5,1:17
2,6,1:17
2,7,1:17
3,-1,1:17
3,0,1:17
3,1,1:17
3,2,1:17
3,3,1:17
3,4,1:17
3,5,1:17
3,6,1:17
3,7,1:17
4,0,1:17
4,1,1:17
4,3,1:17
4,4,1:17
4,5,1:17
4,6,1:17
4,7,1:17
5,4,1:17
5,5,1:17
5,6,1:17
5,7,1:17
5,8,1:17
6,5,1:17
6,6,1:17
6,7,1:17
6,8,1:17
7,8,1:17
7,9,1:17
8,9,1:17
8,10,1:17
9,10,1:17
9,11,1:17
-12,6,2:17
-11,2,2:17
-11,5,2:17
-11,6,2:17
-11,7,2:17
-10,2,2:17
-10,3,2:17
-10,4,2:17
-10,5,2:17
-10,6,2:17
-9,-11,2:17
-9,-8,2:17
-9,1,2:17
-9,2,2:17
-9,3,2:17
-9,4,2:17
-9,5,2:17
-8,-13,2:17
-8,-12,2:17
-8,-11,2:17
-8,-10,2:17
-8,-9,2:17
-8,-8,2:17
-8,-7,2:17
-8,-6,2:17
-8,-5,2:17
-8,-4,2:17
-8,-3,2:17
-8,-2,2:17
-8,-1,2:17
-8,0,2:17
-8,1,2:17
-8,2,2:17
-8,3,2:17
-8,4,2:17
-8,5,2:17
-7,-13,2:17
-7,-12,2:17
-7,-11,2:17
-7,-10,2:17
-7,-9,2:17
-7,-8,2:17
-7,-7,2:17
-7,-6,2:17
-7,-5,2:17
-7,-4,2:17
-7,-3,2:17
-7,-2,2:17
-7,-1,2:17
-7,0,2:17
-7,1,2:17
-7,2,2:17
-7,4,2:17
-6,-12,2:17
-6,-11,2:17
-6,-10,2:17
-6,-9,2:17
-6,-8,2:17
-6,-7,2:17
-6,-6,2:17
-6,-5,2:17
-6,-4,2:17
-6,-3,2:17
-6,-2,2:17
-6,-1,2:17
-6,0,2:17
-6,1,2:17
-6,2,2:17
-5,-9,2:17
-5,-8,2:17
-5,-7,2:17
-5,-6,2:17
-5,-5,2:17
-5,-4,2:17
-5,-3,2:17
-5,-2,2:17
-5,-1,2:17
-5,0,2:17
-5,1,2:17
-5,2,2:17
-4,-8,2:17
-4,-7,2:17
-4,-6,2:17
-4,-5,2:17
-4,-4,2:17
-4,-3,2:17
-4,-2,2:17
-4,-1,2:17
-4,0,2:17
-4,1,2:17
-3,-6,2:17
-3,-5,2:17
-3,-4,2:17
-3,-3,2:17
-3,-2,2:17
-3,-1,2:17
-3,0,2:17
-3,1,2:17
-3,2,2:17
-2,-6,2:17
-2,-5,2:17
-2,-4,2:17
-2,-3,2:17
-2,-2,2:17
-2,-1,2:17
-2,0,2:17
-2,1,2:17
-2,2,2:17
-1,-7,2:17
-1,-6,2:17
-1,-5,2:17
-1,-4,2:17
-1,-3,2:17
-1,-2,2:17
-1,-1,2:17
-1,0,2:17
-1,1,2:17
-1,2,2:17
-1,3,2:17
0,-6,2:17
0,-5,2:17
0,-4,2:17
0,-3,2:17
0,-2,2:17
0,0,2:17
0,1,2:17
0,2,2:17
0,3,2:17
1,-7,2:17
1,-6,2:17
1,-5,2:17
1,-3,2:17
1,0,2:17
1,1,2:17
1,2,2:17
1,3,2:17
1,4,2:17
2,0,2:17
2,1,2:17
2,2,2:17
2,3,2:17
2,4,2:17
2,5,2:17
2,6,2:17
3,0,2:17
3,3,2:17
3,4,2:17
3,5,2:17
3,6,2:17
4,4,2:17
4,5,2:17
4,6,2:17
4,7,2:17
5,5,2:17
5,6,2:17
5,7,2:17
6,6,2:17
-8,-9,3:17
-8,-8,3:17
-8,-7,3:17
-8,-6,3:17
-8,-5,3:17
-8,-4,3:17
-8,-1,3:17
-8,0,3:17
-8,1,3:17
-7,-10,3:17
-7,-9,3:17
-7,-8,3:17
-7,-7,3:17
-7,-6,3:17
-7,-5,3:17
-7,-4,3:17
-7,-3,3:17
-7,-2,3:17
-7,-1,3:17
-7,0,3:17
-7,1,3:17
-6,-11,3:17
-6,-10,3:17
-6,-9,3:17
-6,-8,3:17
-6,-7,3:17
-6,-6,3:17
-6,-5,3:17
-6,-4,3:17
-6,-3,3:17
-6,-2,3:17
-6,-1,3:17
-6,0,3:17
-6,1,3:17
-5,-10,3:17
-5,-9,3:17
-5,-8,3:17
-5,-7,3:17
-5,-6,3:17
-5,-5,3:17
-5,-4,3:17
-5,-3,3:17
-5,-2,3:17
-5,-1,3:17
-5,0,3:17
-5,1,3:17
-5,2,3:17
-4,-8,3:17
-4,-7,3:17
-4,-6,3:17
-4,-5,3:17
-4,-4,3:17
-4,-3,3:17
-4,-2,3:17
-4,-1,3:17
-4,0,3:17
-4,1,3:17
-3,-7,3:17
-3,-6,3:17
-3,-5,3:17
-3,-4,3:17
-3,-3,3:17
-3,-2,3:17
-3,-1,3:17
-3,0,3:17
-3,1,3:17
-2,-6,3:17
-2,-5,3:17
-2,-4,3:17
-2,-3,3:17
-2,-2,3:17
-2,-1,3:17
-2,0,3:17
-2,1,3:17
-2,2,3:17
-1,-6,3:17
-1,-4,3:17
-1,-3,3:17
-1,-2,3:17
-1,-1,3:17
-1,0,3:17
-1,1,3:17
-1,2,3:17
0,-6,3:17
0,-4,3:17
0,-3,3:17
0,-2,3:17
0,0,3:17
0,1,3:17
4,6,3:17
5,6,3:17
-7,-8,4:17
-7,-7,4:17
-7,-6,4:17
-7,-5,4:17
-7,-4,4:17
-7,-3,4:17
-7,-2,4:17
-7,-1,4:17
-6,-9,4:17
-6,-8,4:17
-6,-7,4:17
-6,-6,4:17
-6,-5,4:17
-6,-4,4:17
-6,-3,4:17
-6,-2,4:17
-6,-1,4:17
-6,0,4:17
-5,-9,4:17
-5,-8,4:17
-5,-7,4:17
-5,-6,4:17
-5,-5,4:17
-5,-4,4:17
-5,-3,4:17
-5,-2,4:17
-5,-1,4:17
-5,0,4:17
-4,-8,4:17
-4,-7,4:17
-4,-6,4:17
-4,-5,4:17
-4,-4,4:17
-4,-3,4:17
-4,-2,4:17
-4,-1,4:17
-4,0,4:17
-3,-7,4:17
-3,-6,4:17
-3,-5,4:17
-3,-4,4:17
-3,-3,4:17
-3,-2,4:17
-3,-1,4:17
-2,-5,4:17
-2,-4,4:17
-2,-3,4:17
-2,-2,4:17
-2,-1,4:17
-1,-4,4:17
-1,-3,4:17
-1,-2,4:17
-1,-1,4:17
-1,1,4:17
0,-4,4:17
0,-3,4:17
0,-2,4:17
-7,-7,5:17
-7,-6,5:17
-7,-5,5:17
-7,-4,5:17
-6,-8,5:17
-6,-7,5:17
-6,-6,5:17
-6,-5,5:17
-6,-4,5:17
-6,-3,5:17
-6,-2,5:17
-6,-1,5:17
-5,-8,5:17
-5,-7,5:17
-5,-6,5:17
-5,-5,5:17
-5,-4,5:17
-5,-3,5:17
-5,-2,5:17
-5,-1,5:17
-4,-8,5:17
-4,-7,5:17
-4,-6,5:17
-4,-5,5:17
-4,-4,5:17
-4,-3,5:17
-4,-2,5:17
-4,-1,5:17
-3,-7,5:17
-3,-6,5:17
-3,-5,5:17
-3,-4,5:17
-3,-3,5:17
-3,-2,5:17
-3,-1,5:17
-2,-4,5:17
-2,-3,5:17
-2,-2,5:17
-2,-1,5:17
-1,-5,5:17
-1,-4,5:17
-1,-3,5:17
-1,-2,5:17
-1,-1,5:17
0,-4,5:17
-7,-6,6:17
-7,-5,6:17
-6,-7,6:17
-6,-6,6:17
-6,-5,6:17
-6,-4,6:17
-6,-3,6:17
-5,-8,6:17
-5,-7,6:17
-5,-6,6:17
-5,-5,6:17
-5,-4,6:17
-5,-3,6:17
-4,-7,6:17
-4,-6,6:17
-4,-5,6:17
-4,-4,6:17
-4,-3,6:17
-4,-2,6:17
-4,-1,6:17
-3,-6,6:17
-3,-5,6:17
-3,-4,6:17
-3,-3,6:17
-3,-2,6:17
-3,-1,6:17
-2,-4,6:17
-2,-3,6:17
-2,-2,6:17
-2,-1,6:17
-1,-4,6:17
-1,-3,6:17
-1,-2,6:17
-6,-6,7:17
-6,-5,7:17
-6,-4,7:17
-5,-7,7:17
-5,-6,7:17
-5,-5,7:17
-5,-4,7:17
-5,-3,7:17
-4,-7,7:17
-4,-6,7:17
-4,-5,7:17
-4,-4,7:17
-4,-3,7:17
-4,-2,7:17
-3,-5,7:17
-3,-4,7:17
-3,-3,7:17
-3,-2,7:17
-2,-4,7:17
-2,-3,7:17
-2,-2,7:17
-1,-3,7:17
-1,-2,7:17
-6,-6,8:17
-6,-5,8:17
-6,-4,8:17
-5,-7,8:17
-5,-6,8:17
-5,-5,8:17
-5,-4,8:17
-5,-3,8:17
-4,-6,8:17
-4,-5,8:17
-4,-4,8:17
-4,-3,8:17
-4,-2,8:17
-3,-5,8:17
-3,-4,8:17
-3,-3,8:17
-3,-2,8:17
-3,-1,8:17
-2,-4,8:17
-2,-3,8:17
-2,-2,8:17
-1,-3,8:17
-1,-2,8:17
-5,-6,9:17
-5,-5,9:17
-5,-4,9:17
-5,-3,9:17
-4,-6,9:17
-4,-5,9:17
-4,-4,9:17
-4,-3,9:17
-4,-2,9:17
-3,-5,9:17
-3,-4,9:17
-3,-3,9:17
-3,-2,9:17
-3,-1,9:17
-2,-4,9:17
-2,-3,9:17
-2,-2,9:17
-2,-1,9:17
-1,-3,9:17
-1,-2,9:17
-1,-1,9:17
0,-2,9:17
-5,-5,10:17
-5,-4,10:17
-5,-3,10:17
-5,-2,10:17
-4,-5,10:17
-4,-4,10:17
-4,-3,10:17
-4,-2,10:17
-4,-1,10:17
-3,-4,10:17
-3,-3,10:17
-3,-2,10:17
-3,-1,10:17
-2,-4,10:17
-2,-3,10:17
-2,-2,10:17
-2,-1,10:17
-1,-4,10:17
-1,-3,10:17
-1,-2,10:17
-1,-1,10:17
0,-2,10:17
-5,-4,11:17
-5,-3,11:17
-5,-2,11:17
-4,-5,11:17
-4,-4,11:17
-4,-3,11:17
-4,-2,11:17
-4,-1,11:17
-3,-4,11:17
-3,-3,11:17
-3,-2,11:17
-3,-1,11:17
-2,-4,11:17
-2,-3,11:17
-2,-2,11:17
-2,-1,11:17
-1,-4,11:17
-1,-3,11:17
-1,-2,11:17
-1,-1,11:17
0,-3,11:17
0,-2,11:17
-4,-4,12:17
-4,-3,12:17
-4,-2,12:17
-3,-3,12:17
-3,-2,12:17
-3,-1,12:17
-2,-4,12:17
-2,-3,12:17
-2,-2,12:17
-2,-1,12:17
-2,0,12:17
-1,-4,12:17
-1,-3,12:17
-1,-2,12:17
-1,-1,12:17
0,-3,12:17
0,-2,12:17
0,-1,12:17
-4,-2,13:17
-3,-3,13:17
-3,-2,13:17
-3,-1,13:17
-3,0,13:17
-2,-2,13:17
-2,-1,13:17
-2,0,13:17
-1,-3,13:17
-1,-2,13:17
-1,-1,13:17
-1,0,13:17
0,-2,13:17
0,-1,13:17
0,0,13:17
-4,-2,14:17
-3,-3,14:17
-3,-2,14:17
-3,-1,14:17
-2,-3,14:17
-2,-2,14:17
-2,-1,14:17
-2,0,14:17
-1,-3,14:17
-1,-2,14:17
-1,-1,14:17
-1,0,14:17
0,-2,14:17
0,-1,14:17
0,0,14:17
1,-2,14:17
1,-1,14:17
-3,-2,15:17
-3,-1,15:17
-2,-2,15:17
-2,-1,15:17
-2,0,15:17
-1,-3,15:17
-1,-2,15:17
-1,-1,15:17
-1,0,15:17
-1,1,15:17
0,-3,15:17
0,-2,15:17
0,-1,15:17
0,0,15:17
1,-3,15:17
1,-2,15:17
1,-1,15:17
2,-2,15:17
2,-1,15:17
-3,-1,16:17
-2,-2,16:17
-2,-1,16:17
-2,0,16:17
-1,-2,16:17
-1,-1,16:17
-1,0,16:17
-1,1,16:17
0,-3,16:17
0,-2,16:17
0,-1,16:17
0,0,16:17
0,1,16:17
1,-3,16:17
1,-2,16:17
1,-1,16:17
1,0,16:17
2,-3,16:17
2,-2,16:17
2,-1,16:17
3,-1,16:17
-3,-1,17:17
-2,-2,17:17
-2,-1,17:17
-2,0,17:17
-1,-2,17:17
-1,-1,17:17
-1,0,17:17
0,-3,17:17
0,-2,17:17
0,-1,17:17
0,0,17:17
0,1,17:17
1,-3,17:17
1,-2,17:17
1,-1,17:17
1,0,17:17
2,-3,17:17
2,-2,17:17
2,-1,17:17
2,0,17:17
3,-2,17:17
3,-1,17:17
3,0,17:17
4,-1,17:17
-2,-1,18:17
-1,-2,18:17
-1,-1,18:17
-1,0,18:17
0,-2,18:17
0,-1,18:17
0,0,18:17
1,-2,18:17
1,-1,18:17
1,0,18:17
2,-2,18:17
2,-1,18:17
2,0,18:17
3,-2,18:17
3,-1,18:17
3,0,18:17
4,-2,18:17
4,-1,18:17
4,0,18:17
-1,-2,19:17
-1,-1,19:17
-1,0,19:17
0,-2,19:17
0,-1,19:17
0,0,19:17
1,-2,19:17
1,-1,19:17
1,0,19:17
2,-2,19:17
2,-1,19:17
2,0,19:17
3,-2,19:17
3,-1,19:17
3,0,19:17
4,-1,19:17
4,0,19:17
-1,-1,20:17
0,-2,20:17
0,-1,20:17
0,0,20:17
1,-2,20:17
1,-1,20:17
1,0,20:17
2,-2,20:17
2,-1,20:17
2,0,20:17
3,-3,20:17
3,-2,20:17
3,-1,20:17
3,0,20:17
4,-1,20:17
4,0,20:17
-1,-1,21:17
0,-2,21:17
0,-1,21:17
0,0,21:17
1,-2,21:17
1,-1,21:17
1,0,21:17
2,-2,21:17
2,-1,21:17
2,0,21:17
3,-3,21:17
3,-2,21:17
3,-1,21:17
3,0,21:17
3,1,21:17
4,-2,21:17
4,-1,21:17
4,0,21:17
5,-1,21:17
0,-2,22:17
0,-1,22:17
0,0,22:17
1,-2,22:17
1,-1,22:17
1,0,22:17
2,-3,22:17
2,-2,22:17
2,-1,22:17
2,0,22:17
2,1,22:17
3,-3,22:17
3,-2,22:17
3,-1,22:17
3,0,22:17
3,1,22:17
4,-3,22:17
4,-2,22:17
4,-1,22:17
4,0,22:17
4,1,22:17
5,-1,22:17
1,-2,23:17
1,-1,23:17
1,0,23:17
2,-3,23:17
2,-2,23:17
2,-1,23:17
2,0,23:17
2,1,23:17
3,-3,23:17
3,-2,23:17
3,-1,23:17
3,0,23:17
3,1,23:17
4,-3,23:17
4,-2,23:17
4,-1,23:17
4,0,23:17
4,1,23:17
5,-2,23:17
5,-1,23:17
5,0,23:17
1,-2,24:17
1,-1,24:17
1,0,24:17
2,-3,24:17
2,-2,24:17
2,-1,24:17
2,0,24:17
2,1,24:17
3,-3,24:17
3,-2,24:17
3,-1,24:17
3,0,24:17
3,1,24:17
4,-3,24:17
4,-2,24:17
4,-1,24:17
4,0,24:17
4,1,24:17
5,-3,24:17
5,-2,24:17
5,-1,24:17
5,0,24:17
5,1,24:17
6,-2,24:17
6,-1,24:17
1,-2,25:17
1,-1,25:17
2,-2,25:17
2,-1,25:17
2,0,25:17
3,-3,25:17
3,-2,25:17
3,-1,25:17
3,0,25:17
3,1,25:17
4,-3,25:17
4,-2,25:17
4,-1,25:17
4,0,25:17
4,1,25:17
5,-3,25:17
5,-2,25:17
5,-1,25:17
5,0,25:17
5,1,25:17
6,-2,25:17
6,-1,25:17
2,-2,26:17
2,-1,26:17
3,-3,26:17
3,-2,26:17
3,-1,26:17
3,0,26:17
3,1,26:17
4,-3,26:17
4,-2,26:17
4,-1,26:17
4,0,26:17
4,1,26:17
5,-3,26:17
5,-2,26:17
5,-1,26:17
5,0,26:17
5,1,26:17
6,-2,26:17
6,-1,26:17
2,-3,27:17
2,-2,27:17
2,-1,27:17
3,-3,27:17
3,-2,27:17
3,-1,27:17
3,0,27:17
4,-3,27:17
4,-2,27:17
4,-1,27:17
4,0,27:17
4,1,27:17
5,-3,27:17
5,-2,27:17
5,-1,27:17
5,0,27:17
6,-3,27:17
6,-2,27:17
6,-1,27:17
1,-2,28:17
2,-3,28:17
2,-2,28:17
2,-1,28:17
2,0,28:17
3,-3,28:17
3,-2,28:17
3,-1,28:17
3,0,28:17
4,-3,28:17
4,-2,28:17
4,-1,28:17
4,0,28:17
4,1,28:17
5,-3,28:17
5,-2,28:17
5,-1,28:17
5,0,28:17
6,-3,28:17
6,-2,28:17
6,-1,28:17
1,-3,29:17
1,-2,29:17
2,-3,29:17
2,-2,29:17
2,-1,29:17
2,0,29:17
3,-3,29:17
3,-2,29:17
3,-1,29:17
3,0,29:17
4,-3,29:17
4,-2,29:17
4,-1,29:17
4,0,29:17
5,-3,29:17
5,-2,29:17
5,-1,29:17
5,0,29:17
6,-3,29:17
6,-2,29:17
7,-2,29:17
1,-3,30:17
1,-2,30:17
1,-1,30:17
1,1,30:17
2,-3,30:17
2,-2,30:17
2,-1,30:17
2,0,30:17
3,-3,30:17
3,-2,30:17
3,-1,30:17
3,0,30:17
4,-3,30:17
4,-2,30:17
4,-1,30:17
4,0,30:17
5,-3,30:17
5,-2,30:17
5,-1,30:17
6,-3,30:17
6,-2,30:17
6,-1,30:17
7,-2,30:17
0,0,31:17
0,1,31:17
0,2,31:17
1,-4,31:17
1,-3,31:17
1,-2,31:17
1,-1,31:17
1,0,31:17
1,1,31:17
1,2,31:17
2,-4,31:17
2,-3,31:17
2,-2,31:17
2,-1,31:17
2,0,31:17
2,1,31:17
2,2,31:17
3,-4,31:17
3,-3,31:17
3,-2,31:17
3,-1,31:17
3,0,31:17
3,1,31:17
4,-4,31:17
4,-3,31:17
4,-2,31:17
4,-1,31:17
4,0,31:17
4,1,31:17
5,-4,31:17
5,-3,31:17
5,-2,31:17
5,-1,31:17
5,0,31:17
5,1,31:17
6,-4,31:17
6,-3,31:17
6,-2,31:17
6,-1,31:17
6,0,31:17
6,1,31:17
7,-4,31:17
7,-3,31:17
7,-2,31:17
0,-3,31:18.0
-1,-3,31:18.0
-1,-4,31:18.0
-1,-2,31:18.0
-2,-3,31:18.0
6,2,31:18.0
6,3,31:18.0
7,3,31:18.0
6,-5,31:18.0
-2,-5,32:17
-1,-4,32:17
-1,1,32:17
-1,2,32:17
-1,3,32:17
0,-3,32:17
0,-2,32:17
0,-1,32:17
0,0,32:17
0,1,32:17
0,2,32:17
0,3,32:17
1,-4,32:17
1,-3,32:17
1,-2,32:17
1,-1,32:17
1,0,32:17
1,1,32:17
1,2,32:17
1,3,32:17
2,-5,32:17
2,-4,32:17
2,-3,32:17
2,-2,32:17
2,-1,32:17
2,0,32:17
2,1,32:17
2,2,32:17
3,-5,32:17
3,-4,32:17
3,-3,32:17
3,-2,32:17
3,-1,32:17
3,0,32:17
3,1,32:17
3,2,32:17
4,-5,32:17
4,-4,32:17
4,-3,32:17
4,-2,32:17
4,-1,32:17
4,0,32:17
4,1,32:17
4,2,32:17
5,-5,32:17
5,-4,32:17
5,-3,32:17
5,-2,32:17
5,-1,32:17
5,0,32:17
5,1,32:17
5,2,32:17
6,-7,32:17
6,-6,32:17
6,-5,32:17
6,-4,32:17
6,-3,32:17
6,-2,32:17
6,-1,32:17
6,0,32:17
6,1,32:17
7,-7,32:17
7,-6,32:17
7,-5,32:17
7,-4,32:17
7,-3,32:17
7,-2,32:17
7,1,32:17
7,2,32:17
8,-7,32:17
8,-6,32:17
8,-5,32:17
8,-4,32:17
8,-3,32:17
-3,-6,33:17
-3,-5,33:17
-3,-4,33:17
-2,-6,33:17
-2,-5,33:17
-2,-4,33:17
-2,-3,33:17
-2,2,33:17
-2,4,33:17
-1,-6,33:17
-1,-5,33:17
-1,-4,33:17
-1,-3,33:17
-1,-2,33:17
-1,1,33:17
-1,2,33:17
-1,3,33:17
0,-5,33:17
0,-4,33:17
0,-3,33:17
0,-2,33:17
0,-1,33:17
0,0,33:17
0,1,33:17
0,2,33:17
0,3,33:17
0,4,33:17
1,-5,33:17
1,-4,33:17
1,-3,33:17
1,-2,33:17
1,-1,33:17
1,0,33:17
1,1,33:17
1,2,33:17
1,3,33:17
2,-5,33:17
2,-4,33:17
2,-3,33:17
2,-2,33:17
2,-1,33:17
2,0,33:17
2,1,33:17
2,2,33:17
3,-5,33:17
3,-4,33:17
3,-3,33:17
3,-2,33:17
3,-1,33:17
3,0,33:17
3,1,33:17
3,2,33:17
4,-5,33:17
4,-4,33:17
4,-3,33:17
4,-2,33:17
4,-1,33:17
4,0,33:17
4,1,33:17
4,2,33:17
5,-5,33:17
5,-4,33:17
5,-3,33:17
5,-2,33:17
5,-1,33:17
5,0,33:17
5,1,33:17
5,2,33:17
6,-7,33:17
6,-6,33:17
6,-5,33:17
6,-4,33:17
6,-3,33:17
6,-2,33:17
6,-1,33:17
6,0,33:17
6,1,33:17
6,2,33:17
6,3,33:17
7,-8,33:17
7,-7,33:17
7,-6,33:17
7,-5,33:17
7,-4,33:17
7,-3,33:17
7,-2,33:17
7,-1,33:17
7,0,33:17
7,1,33:17
7,2,33:17
7,3,33:17
8,-8,33:17
8,-7,33:17
8,-6,33:17
8,-5,33:17
8,-4,33:17
8,-3,33:17
8,2,33:17
8,3,33:17
9,-8,33:17
9,-7,33:17
9,-6,33:17
9,-4,33:17
-4,-6,33:18.0
-5,-6,33:18.0
-5,-5,33:18.0
-4,-5,33:18.0
8,4,33:18.0
7,4,33:18.0
3,3,33:18.0
4,3,33:18.0
2,-6,33:18.0
2,-7,33:18.0
3,-6,33:18.0
3,-7,33:18.0
-2,0,33:18.0
-2,1,33:18.0
-3,0,33:18.0
10,-7,33:18.0
-5,-8,34:17
-4,-7,34:17
-4,-5,34:17
-4,6,34:17
-3,-6,34:17
-3,-5,34:17
-3,-4,34:17
-3,3,34:17
-3,4,34:17
-3,5,34:17
-2,-7,34:17
-2,-6,34:17
-2,-5,34:17
-2,-4,34:17
-2,-3,34:17
-2,3,34:17
-2,4,34:17
-2,5,34:17
-1,-6,34:17
-1,-5,34:17
-1,-4,34:17
-1,-3,34:17
-1,-2,34:17
-1,1,34:17
-1,2,34:17
-1,3,34:17
-1,4,34:17
-1,5,34:17
0,-5,34:17
0,-4,34:17
0,-3,34:17
0,-2,34:17
0,-1,34:17
0,0,34:17
0,1,34:17
0,2,34:17
0,3,34:17
1,-4,34:17
1,-3,34:17
1,-2,34:17
1,-1,34:17
1,0,34:17
1,1,34:17
1,2,34:17
1,3,34:17
2,-5,34:17
2,-4,34:17
2,-3,34:17
2,-2,34:17
2,-1,34:17
2,0,34:17
2,1,34:17
2,2,34:17
3,-5,34:17
3,-4,34:17
3,-3,34:17
3,-1,34:17
3,0,34:17
3,1,34:17
3,2,34:17
4,-5,34:17
4,-4,34:17
4,-3,34:17
4,0,34:17
4,1,34:17
4,2,34:17
4,3,34:17
5,-5,34:17
5,-4,34:17
5,-3,34:17
5,-1,34:17
5,0,34:17
5,1,34:17
5,2,34:17
5,3,34:17
6,-7,34:17
6,-6,34:17
6,-5,34:17
6,-4,34:17
6,-3,34:17
6,-1,34:17
6,0,34:17
6,1,34:17
6,2,34:17
6,3,34:17
7,-8,34:17
7,-7,34:17
7,-6,34:17
7,-5,34:17
7,-4,34:17
7,-3,34:17
7,-1,34:17
7,0,34:17
7,1,34:17
7,2,34:17
7,3,34:17
7,4,34:17
8,-9,34:17
8,-8,34:17
8,-7,34:17
8,-6,34:17
8,-5,34:17
8,-4,34:17
8,-3,34:17
8,1,34:17
8,2,34:17
8,3,34:17
8,4,34:17
9,-9,34:17
9,-8,34:17
9,-7,34:17
9,-6,34:17
10,-10,34:17
10,-9,34:17
10,-8,34:17
10,-7,34:17
-6,-9,35:17
-6,-8,35:17
-6,-7,35:17
-5,-9,35:17
-5,-8,35:17
-5,-7,35:17
-5,-6,35:17
-5,5,35:17
-5,6,35:17
-5,7,35:17
-4,-9,35:17
-4,-8,35:17
-4,-7,35:17
-4,-6,35:17
-4,-5,35:17
-4,4,35:17
-4,5,35:17
-4,6,35:17
-3,-8,35:17
-3,-7,35:17
-3,-6,35:17
-3,-5,35:17
-3,-4,35:17
-3,3,35:17
-3,4,35:17
-3,5,35:17
-3,6,35:17
-2,-7,35:17
-2,-6,35:17
-2,-5,35:17
-2,-4,35:17
-2,-3,35:17
-2,2,35:17
-2,3,35:17
-2,4,35:17
-2,5,35:17
-2,6,35:17
-1,-6,35:17
-1,-5,35:17
-1,-4,35:17
-1,-3,35:17
-1,-2,35:17
-1,1,35:17
-1,2,35:17
-1,3,35:17
-1,4,35:17
-1,5,35:17
0,-5,35:17
0,-4,35:17
0,-3,35:17
0,-2,35:17
0,0,35:17
0,1,35:17
0,2,35:17
0,3,35:17
0,4,35:17
1,-4,35:17
1,-3,35:17
1,-2,35:17
1,0,35:17
1,1,35:17
1,2,35:17
1,3,35:17
2,0,35:17
2,1,35:17
2,2,35:17
4,3,35:17
5,2,35:17
5,3,35:17
6,1,35:17
6,2,35:17
6,3,35:17
7,-8,35:17
7,-7,35:17
7,-6,35:17
7,1,35:17
7,2,35:17
7,3,35:17
7,4,35:17
7,5,35:17
8,-10,35:17
8,-9,35:17
8,-8,35:17
8,-7,35:17
8,-6,35:17
8,2,35:17
8,3,35:17
8,4,35:17
8,5,35:17
9,-11,35:17
9,-10,35:17
9,-9,35:17
9,-8,35:17
9,-7,35:17
9,-6,35:17
9,4,35:17
9,5,35:17
10,-11,35:17
10,-10,35:17
10,-9,35:17
10,-8,35:17
10,-7,35:17
11,-11,35:17
11,-10,35:17
11,-9,35:17
11,-8,35:17
10,-5,35:18.0
10,-6,35:18.0
11,-5,35:18.0
-5,-4,35:18.0
-5,-3,35:18.0
-4,-4,35:18.0
0,5,35:18.0
1,5,35:18.0
1,6,35:18.0
0,6,35:18.0
8,-1,35:18.0
8,0,35:18.0
7,0,35:18.0
-7,-10,36:17
-7,-9,36:17
-7,-8,36:17
-7,7,36:17
-7,8,36:17
-7,9,36:17
-6,-10,36:17
-6,-9,36:17
-6,-8,36:17
-6,-7,36:17
-6,6,36:17
-6,7,36:17
-6,8,36:17
-6,9,36:17
-5,-10,36:17
-5,-9,36:17
-5,-8,36:17
-5,-7,36:17
-5,-6,36:17
-5,5,36:17
-5,6,36:17
-5,7,36:17
-5,8,36:17
-4,-9,36:17
-4,-8,36:17
-4,-7,36:17
-4,-6,36:17
-4,-5,36:17
-4,4,36:17
-4,5,36:17
-4,6,36:17
-4,7,36:17
-3,-8,36:17
-3,-7,36:17
-3,-6,36:17
-3,-5,36:17
-3,-4,36:17
-3,3,36:17
-3,4,36:17
-3,5,36:17
-3,6,36:17
-3,7,36:17
-2,-7,36:17
-2,-6,36:17
-2,-5,36:17
-2,-4,36:17
-2,2,36:17
-2,3,36:17
-2,4,36:17
-2,5,36:17
-2,6,36:17
-1,-6,36:17
-1,-5,36:17
-1,-4,36:17
-1,1,36:17
-1,2,36:17
-1,3,36:17
-1,4,36:17
-1,5,36:17
0,1,36:17
0,2,36:17
0,3,36:17
0,4,36:17
1,1,36:17
1,2,36:17
1,3,36:17
5,2,36:17
6,-11,36:17
6,2,36:17
6,3,36:17
6,4,36:17
7,-12,36:17
7,-11,36:17
7,-9,36:17
7,2,36:17
7,3,36:17
7,4,36:17
7,5,36:17
8,-10,36:17
8,-9,36:17
8,-8,36:17
8,-7,36:17
8,2,36:17
8,3,36:17
8,4,36:17
8,5,36:17
8,6,36:17
9,-12,36:17
9,-11,36:17
9,-10,36:17
9,-9,36:17
9,-8,36:17
9,-7,36:17
9,3,36:17
9,4,36:17
9,5,36:17
9,6,36:17
10,-12,36:17
10,-11,36:17
10,-10,36:17
10,-9,36:17
10,-8,36:17
10,-7,36:17
10,5,36:17
10,6,36:17
11,-12,36:17
11,-11,36:17
11,-10,36:17
11,-9,36:17
11,-8,36:17
11,6,36:17
11,7,36:17
12,-13,36:17
5,-9,36:18.0
5,-8,36:18.0
6,-8,36:18.0
6,-9,36:18.0
6,-10,36:18.0
5,-10,36:18.0
-6,-6,36:18.0
-6,-5,36:18.0
-7,-5,36:18.0
-7,-4,36:18.0
-6,-4,36:18.0
10,4,36:18.0
11,4,36:18.0
-5,4,36:18.0
-6,4,36:18.0
-6,5,36:18.0
-8,-11,37:17
-8,4,37:0
-8,5,37:0
-8,8,37:17
-8,9,37:17
-8,10,37:17
-7,-13,37:17
-7,-12,37:17
-7,-11,37:17
-7,-10,37:17
-7,-9,37:17
-7,-8,37:17
-7,7,37:17
-7,8,37:17
-7,9,37:17
-7,10,37:17
-6,-12,37:17
-6,-11,37:17
-6,-10,37:17
-6,-9,37:17
-6,-8,37:17
-6,-7,37:17
-6,6,37:17
-6,7,37:17
-6,8,37:17
-6,9,37:17
-6,10,37:17
-5,-13,37:17
-5,-12,37:17
-5,-10,37:17
-5,-9,37:17
-5,-8,37:17
-5,-7,37:17
-5,-6,37:17
-5,5,37:17
-5,6,37:17
-5,7,37:17
-5,8,37:17
-5,9,37:17
-4,-9,37:17
-4,-8,37:17
-4,-7,37:17
-4,-6,37:17
-4,-5,37:17
-4,4,37:17
-4,5,37:17
-4,6,37:17
-4,7,37:17
-4,8,37:17
-4,11,37:0
-3,-8,37:17
-3,-7,37:17
-3,-6,37:17
-3,-5,37:17
-3,-4,37:17
-3,3,37:17
-3,4,37:17
-3,5,37:17
-3,6,37:17
-3,7,37:17
-3,12,37:0
-3,13,37:0
-2,-7,37:17
-2,-6,37:17
-2,-5,37:17
-2,-4,37:17
-2,2,37:17
-2,3,37:17
-2,4,37:17
-2,5,37:17
-2,6,37:17
-1,-6,37:17
-1,-5,37:17
-1,-4,37:17
-1,2,37:17
-1,3,37:17
-1,4,37:17
-1,5,37:17
0,2,37:17
0,3,37:17
0,4,37:17
4,-13,37:17
4,-12,37:17
4,-11,37:17
5,-13,37:17
5,-12,37:17
5,-11,37:17
6,-12,37:17
6,-11,37:17
6,-10,37:17
6,7,37:17
6,8,37:0
6,9,37:0
7,-13,37:17
7,-12,37:17
7,-11,37:17
7,-10,37:17
7,3,37:17
7,4,37:17
7,5,37:17
7,6,37:17
8,-12,37:17
8,-11,37:17
8,-10,37:17
8,-9,37:17
8,-8,37:17
8,3,37:17
8,4,37:17
8,5,37:17
8,6,37:17
8,7,37:17
9,-13,37:17
9,-12,37:17
9,-11,37:17
9,-10,37:17
9,-9,37:17
9,-8,37:17
9,3,37:17
9,4,37:17
9,5,37:17
9,6,37:17
10,-13,37:17
10,-12,37:17
10,-11,37:17
10,-10,37:17
10,-9,37:17
10,-8,37:17
10,4,37:17
10,5,37:17
10,6,37:17
10,7,37:17
11,-14,37:17
11,-13,37:17
11,-12,37:17
11,-11,37:17
11,-10,37:17
11,-9,37:17
11,5,37:17
11,6,37:17
11,7,37:17
11,8,37:17
12,-14,37:17
12,-13,37:17
12,-12,37:17
12,-11,37:17
12,-10,37:17
12,6,37:17
12,7,37:17
13,-14,37:17
13,-13,37:17
13,-12,37:17
13,-11,37:17
13,7,37:17
14,-7,37:0
15,-7,37:0
15,-5,37:0
6,10,37:0
-3,11,37:0
-13,2,38:17
-12,1,38:17
-12,2,38:17
-12,3,38:17
-11,-13,38:17
-11,1,38:17
-11,2,38:17
-10,-13,38:17
-10,-12,38:17
-10,1,38:17
-10,2,38:17
-10,3,38:17
-10,4,38:17
-9,-14,38:17
-9,-13,38:17
-9,-12,38:17
-9,-11,38:17
-9,0,38:17
-9,1,38:17
-9,3,38:17
-9,4,38:17
-9,5,38:17
-9,10,38:17
-9,11,38:17
-8,-14,38:17
-8,-13,38:17
-8,-12,38:17
-8,-11,38:17
-8,-10,38:17
-8,-1,38:17
-8,0,38:17
-8,3,38:17
-8,4,38:17
-8,5,38:17
-8,6,38:17
-8,7,38:17
-8,9,38:17
-8,10,38:17
-8,11,38:17
-7,-14,38:17
-7,-13,38:17
-7,-12,38:17
-7,-11,38:17
-7,-10,38:17
-7,-9,38:17
-7,-8,38:17
-7,-2,38:17
-7,-1,38:17
-7,4,38:17
-7,5,38:17
-7,6,38:17
-7,7,38:17
-7,8,38:17
-7,9,38:17
-7,10,38:17
-6,-17,38:17
-6,-13,38:17
-6,-12,38:17
-6,-11,38:17
-6,-10,38:17
-6,-9,38:17
-6,-8,38:17
-6,6,38:17
-6,7,38:17
-6,8,38:17
-6,9,38:17
-5,-15,38:17
-5,-14,38:17
-5,-13,38:17
-5,-12,38:17
-5,-11,38:17
-5,-10,38:17
-5,-9,38:17
-5,-8,38:17
-5,-7,38:17
-5,5,38:17
-5,6,38:17
-5,7,38:17
-5,8,38:17
-5,9,38:17
-5,10,38:17
-5,11,38:17
-4,-14,38:17
-4,-13,38:17
-4,-12,38:17
-4,-8,38:17
-4,-7,38:17
-4,4,38:17
-4,5,38:17
-4,6,38:17
-4,7,38:17
-4,8,38:17
-4,9,38:17
-4,10,38:17
-4,11,38:17
-4,12,38:17
-4,13,38:17
-3,3,38:17
-3,4,38:17
-3,5,38:17
-3,6,38:17
-3,9,38:17
-3,11,38:17
-3,12,38:17
-3,13,38:17
-3,14,38:17
-2,3,38:17
-2,4,38:17
-2,5,38:17
-2,6,38:17
-2,12,38:17
-2,13,38:17
-2,14,38:17
-1,3,38:17
-1,4,38:17
-1,5,38:17
0,-13,38:17
1,-12,38:17
2,-12,38:17
2,-11,38:17
3,-13,38:17
3,-12,38:17
3,-11,38:17
3,-2,38:0
4,-14,38:17
4,-13,38:17
4,-12,38:17
4,-11,38:17
4,-10,38:17
4,-4,38:0
4,-3,38:18.0
4,-2,38:0
4,-1,38:0
4,10,38:17
4,11,38:17
5,-15,38:17
5,-14,38:17
5,-13,38:17
5,-12,38:17
5,-11,38:17
5,-10,38:17
5,-5,38:0
5,-4,38:0
5,-3,38:18.0
5,-2,38:18.0
5,-1,38:0
5,0,38:0
5,7,38:17
5,8,38:17
5,9,38:17
5,10,38:17
6,-13,38:17
6,-12,38:17
6,-11,38:17
6,-10,38:17
6,-6,38:0
6,-5,38:18.0
6,-4,38:18.0
6,-3,38:18.0
6,-2,38:18.0
6,-1,38:18.0
6,0,38:0
6,6,38:17
6,7,38:17
6,8,38:17
6,9,38:17
6,10,38:17
7,-12,38:17
7,-11,38:17
7,-10,38:17
7,-9,38:17
7,-6,38:18.0
7,-5,38:18.0
7,-4,38:18.0
7,-3,38:18.0
7,-2,38:18.0
7,-1,38:18.0
7,0,38:18.0
7,1,38:0
7,5,38:17
7,6,38:17
7,7,38:17
7,8,38:17
7,9,38:17
8,-12,38:17
8,-11,38:17
8,-10,38:17
8,-5,38:18.0
8,-4,38:18.0
8,-3,38:18.0
8,-2,38:18.0
8,-1,38:18.0
8,0,38:18.0
8,1,38:0
8,4,38:17
8,5,38:17
8,6,38:17
8,8,38:17
9,-12,38:17
9,-11,38:17
9,-10,38:17
9,-4,38:18.0
9,-3,38:18.0
9,-2,38:18.0
9,-1,38:18.0
9,0,38:0
9,1,38:0
9,4,38:17
9,5,38:17
9,6,38:17
9,7,38:17
10,-13,38:17
10,-12,38:17
10,-11,38:17
10,-10,38:17
10,-9,38:17
10,-5,38:0
10,-4,38:18.0
10,-3,38:18.0
10,-2,38:18.0
10,-1,38:18.0
10,0,38:18.0
10,1,38:0
10,4,38:17
10,5,38:17
10,6,38:17
10,7,38:17
10,8,38:17
11,-14,38:17
11,-13,38:17
11,-12,38:17
11,-11,38:17
11,-10,38:17
11,-9,38:17
11,-8,38:17
11,-4,38:0
11,-3,38:18.0
11,-2,38:18.0
11,-1,38:18.0
11,0,38:0
11,5,38:17
11,6,38:17
11,7,38:17
11,8,38:17
11,9,38:17
12,-15,38:17
12,-14,38:17
12,-13,38:17
12,-12,38:17
12,-11,38:17
12,-10,38:17
12,-9,38:17
12,-8,38:17
12,-3,38:0
12,-2,38:18.0
12,-1,38:0
12,6,38:17
12,7,38:17
12,8,38:17
13,-15,38:17
13,-14,38:17
13,-13,38:17
13,-12,38:17
13,-11,38:17
13,-10,38:17
13,-9,38:17
13,-8,38:17
13,-7,38:17
13,-2,38:0
13,6,38:17
13,7,38:17
13,8,38:17
14,-15,38:17
14,-14,38:17
14,-13,38:17
14,-11,38:17
14,-8,38:17
14,-7,38:17
14,-6,38:17
14,-5,38:17
14,7,38:17
14,8,38:17
15,-12,38:17
15,-11,38:17
15,-8,38:17
15,-7,38:17
15,-6,38:17
15,-5,38:17
15,-4,38:17
15,7,38:17
16,-11,38:17
16,-7,38:17
16,-6,38:17
16,-5,38:17
16,-4,38:17
17,-12,38:17
17,-5,38:17
17,-4,38:17
17,-3,38:17
18,-12,38:17
9,-5,38:0
11,-5,38:0
13,-1,38:0
-1,-18,38:18.0
0,-18,38:18.0
1,-18,38:18.0
1,-17,38:18.0
0,-17,38:18.0
-1,-17,38:18.0
-1,-16,38:18.0
-2,-17,38:18.0
-2,-18,38:18.0
-2,-19,38:18.0
-10,-6,38:18.0
-11,-6,38:18.0
-11,-5,38:18.0
-11,-4,38:18.0
-10,-4,38:18.0
-9,-4,38:18.0
-9,-5,38:18.0
-10,-5,38:18.0
-9,-6,38:18.0
-10,-7,38:18.0
19,-8,38:18.0
20,-8,38:18.0
20,-7,38:18.0
19,-7,38:18.0
16,-16,38:18.0
17,-16,38:18.0
17,-17,38:18.0
18,-17,38:18.0
18,-16,38:18.0
17,-15,38:18.0
-14,8,38:18.0
-14,9,38:18.0
-13,9,38:18.0
-13,8,38:18.0
-14,7,38:18.0
-15,7,38:18.0
-15,8,38:18.0
1,8,38:18.0
1,9,38:18.0
2,9,38:18.0
-3,0,38:18.0
-3,-1,38:18.0
-4,-1,38:18.0
-4,0,38:18.0
18,1,38:18.0
18,2,38:18.0
18,3,38:18.0
17,3,38:18.0
16,3,38:18.0
16,2,38:18.0
17,2,38:18.0
17,1,38:18.0
17,4,38:18.0
11,11,38:18.0
11,12,38:18.0
11,13,38:18.0
10,13,38:18.0
10,12,38:18.0
12,13,38:18.0
11,14,38:18.0
2,13,38:18.0
2,14,38:18.0
1,14,38:18.0
-7,14,38:18.0
-8,14,38:18.0
-8,15,38:18.0
-9,15,38:18.0
-7,15,38:18.0
-7,16,38:18.0
-16,1,38:18.0
-16,2,38:18.0
-15,2,38:18.0
-16,0,38:18.0
-15,0,38:18.0
-15,-1,38:18.0
-16,-1,38:18.0
-17,-1,38:18.0
8,-19,38:18.0
9,-19,38:18.0
9,-20,38:18.0
10,-20,38:18.0
10,-19,38:18.0
10,-18,38:18.0
-12,-16,38:18.0
-13,-16,38:18.0
-13,-15,38:18.0
-14,-15,38:18.0
-13,-14,38:18.0
-14,-14,38:18.0
-17,-5,39:18
-17,-4,39:18
-17,-3,39:18
-17,1,39:18
-17,2,39:18
-16,-11,39:18
-16,-10,39:18
-16,-7,39:18
-16,-6,39:18
-16,-5,39:18
-16,-4,39:18
-16,-3,39:18
-16,-2,39:18
-16,-1,39:18
-16,0,39:18
-16,1,39:18
-16,2,39:18
-16,3,39:18
-16,4,39:18
-16,6,39:18
-15,-12,39:18
-15,-11,39:18
-15,-10,39:18
-15,-9,39:18
-15,-8,39:18
-15,-7,39:18
-15,-6,39:18
-15,-5,39:18
-15,-4,39:18
-15,-3,39:18
-15,-2,39:18
-15,-1,39:18
-15,0,39:18
-15,1,39:18
-15,2,39:18
-15,3,39:18
-15,4,39:18
-15,5,39:18
-15,6,39:18
-15,7,39:18
-15,8,39:18
-14,-13,39:18
-14,-12,39:18
-14,-11,39:18
-14,-10,39:18
-14,-9,39:18
-14,-8,39:18
-14,-7,39:18
-14,-6,39:18
-14,-5,39:18
-14,-4,39:18
-14,-3,39:18
-14,-2,39:18
-14,-1,39:18
-14,0,39:18
-14,1,39:18
-14,2,39:18
-14,3,39:18
-14,4,39:18
-14,5,39:18
-14,6,39:18
-14,7,39:18
-14,8,39:18
-14,9,39:18
-13,-14,39:18
-13,-13,39:18
-13,-12,39:18
-13,-11,39:18
-13,-10,39:18
-13,-9,39:18
-13,-8,39:18
-13,-7,39:18
-13,-6,39:18
-13,-5,39:18
-13,-4,39:18
-13,-3,39:18
-13,-2,39:18
-13,-1,39:18
-13,0,39:18
-13,1,39:18
-13,2,39:18
-13,3,39:18
-13,4,39:18
-13,5,39:18
-13,6,39:18
-13,7,39:18
-13,8,39:18
-13,9,39:18
-13,10,39:18
-12,-15,39:18
-12,-14,39:18
-12,-13,39:18
-12,-12,39:18
-12,-11,39:18
-12,-10,39:18
-12,-9,39:18
-12,-8,39:18
-12,-7,39:18
-12,-6,39:18
-12,-5,39:18
-12,-4,39:18
-12,-3,39:18
-12,-2,39:18
-12,-1,39:18
-12,0,39:18
-12,1,39:18
-12,2,39:18
-12,3,39:18
-12,4,39:18
-12,5,39:18
-12,6,39:18
-12,7,39:18
-12,8,39:18
-12,9,39:18
-12,10,39:18
-12,11,39:18
-11,-16,39:18
-11,-15,39:18
-11,-14,39:18
-11,-13,39:18
-11,-12,39:18
-11,-11,39:18
-11,-10,39:18
-11,-9,39:18
-11,-8,39:18
-11,-7,39:18
-11,-6,39:18
-11,-5,39:18
-11,-4,39:18
-11,-3,39:18
-11,-2,39:18
-11,-1,39:18
-11,0,39:18
-11,1,39:18
-11,2,39:18
-11,3,39:18
-11,4,39:18
-11,5,39:18
-11,6,39:18
-11,7,39:18
-11,8,39:18
-11,9,39:18
-11,10,39:18
-11,11,39:18
-11,12,39:18
-10,-17,39:18
-10,-16,39:18
-10,-15,39:18
-10,-14,39:18
-10,-13,39:18
-10,-12,39:18
-10,-11,39:18
-10,-10,39:18
-10,-9,39:18
-10,-8,39:18
-10,-7,39:18
-10,-6,39:18
-10,-5,39:18
-10,-4,39:18
-10,-3,39:18
-10,-2,39:18
-10,-1,39:18
-10,0,39:18
-10,1,39:18
-10,2,39:18
-10,3,39:18
-10,4,39:18
-10,5,39:18
-10,6,39:18
-10,7,39:18
-10,8,39:18
-10,9,39:18
-10,10,39:18
-10,11,39:18
-10,12,39:18
-10,13,39:18
-9,-18,39:18
-9,-17,39:18
-9,-16,39:18
-9,-15,39:18
-9,-14,39:18
-9,-13,39:18
-9,-12,39:18
-9,-11,39:18
-9,-10,39:18
-9,-9,39:18
-9,-8,39:18
-9,-7,39:18
-9,-6,39:18
-9,-5,39:18
-9,-4,39:18
-9,-3,39:18
-9,-2,39:18
-9,-1,39:18
-9,0,39:18
-9,1,39:18
-9,2,39:18
-9,3,39:18
-9,4,39:18
-9,5,39:18
-9,6,39:18
-9,7,39:18
-9,8,39:18
-9,9,39:18
-9,10,39:18
-9,11,39:18
-9,12,39:18
-9,13,39:18
-9,14,39:18
-8,-18,39:18
-8,-17,39:18
-8,-16,39:18
-8,-15,39:18
-8,-14,39:18
-8,-13,39:18
-8,-12,39:18
-8,-11,39:18
-8,-10,39:18
-8,-9,39:18
-8,-8,39:18
-8,-7,39:18
-8,-6,39:18
-8,-5,39:18
-8,-4,39:18
-8,-3,39:18
-8,-2,39:18
-8,-1,39:18
-8,0,39:18
-8,1,39:18
-8,2,39:18
-8,3,39:18
-8,4,39:18
-8,5,39:18
-8,6,39:18
-8,7,39:18
-8,8,39:18
-8,9,39:18
-8,10,39:18
-8,11,39:18
-8,12,39:18
-8,13,39:18
-8,14,39:18
-7,-19,39:18
-7,-18,39:18
-7,-17,39:18
-7,-16,39:18
-7,-15,39:18
-7,-14,39:18
-7,-13,39:18
-7,-12,39:18
-7,-11,39:18
-7,-10,39:18
-7,-9,39:18
-7,-8,39:18
-7,-7,39:18
-7,-6,39:18
-7,-5,39:18
-7,-4,39:18
-7,-3,39:18
-7,-2,39:18
-7,-1,39:18
-7,0,39:18
-7,1,39:18
-7,2,39:18
-7,3,39:18
-7,4,39:18
-7,5,39:18
-7,6,39:18
-7,7,39:18
-7,8,39:18
-7,9,39:18
-7,10,39:18
-7,11,39:18
-7,12,39:18
-7,13,39:18
-7,14,39:18
-7,15,39:18
-6,-19,39:18
-6,-18,39:18
-6,-17,39:18
-6,-16,39:18
-6,-15,39:18
-6,-14,39:18
-6,-13,39:18
-6,-12,39:18
-6,-11,39:18
-6,-10,39:18
-6,-9,39:18
-6,-8,39:18
-6,-7,39:18
-6,-6,39:18
-6,-5,39:18
-6,-4,39:18
-6,-3,39:18
-6,-2,39:18
-6,-1,39:18
-6,0,39:18
-6,1,39:18
-6,2,39:18
-6,3,39:18
-6,4,39:18
-6,5,39:18
-6,6,39:18
-6,7,39:18
-6,8,39:18
-6,9,39:18
-6,10,39:18
-6,11,39:18
-6,12,39:18
-6,13,39:18
-6,14,39:18
-6,15,39:18
-5,-20,39:18
-5,-19,39:18
-5,-18,39:18
-5,-17,39:18
-5,-16,39:18
-5,-15,39:18
-5,-14,39:18
-5,-13,39:18
-5,-12,39:18
-5,-11,39:18
-5,-10,39:18
-5,-9,39:18
-5,-8,39:18
-5,-7,39:18
-5,-6,39:18
-5,-5,39:18
-5,-4,39:18
-5,-3,39:18
-5,-2,39:18
-5,-1,39:18
-5,0,39:18
-5,1,39:18
-5,2,39:18
-5,3,39:18
-5,4,39:18
-5,5,39:18
-5,6,39:18
-5,7,39:18
-5,8,39:18
-5,9,39:18
-5,10,39:18
-5,11,39:18
-5,12,39:18
-5,13,39:18
-5,14,39:18
-5,15,39:18
-5,16,39:18
-4,-20,39:18
-4,-19,39:18
-4,-18,39:18
-4,-17,39:18
-4,-16,39:18
-4,-15,39:18
-4,-14,39:18
-4,-13,39:18
-4,-12,39:18
-4,-11,39:18
-4,-10,39:18
-4,-9,39:18
-4,-8,39:18
-4,-7,39:18
-4,-6,39:18
-4,-5,39:18
-4,-4,39:18
-4,-3,39:18
-4,-2,39:18
-4,-1,39:18
-4,0,39:18
-4,1,39:18
-4,2,39:18
-4,3,39:18
-4,4,39:18
-4,5,39:18
-4,6,39:18
-4,7,39:18
-4,8,39:18
-4,9,39:18
-4,10,39:18
-4,11,39:18
-4,12,39:18
-4,13,39:18
-4,14,39:18
-4,15,39:18
-4,16,39:18
-3,-20,39:18
-3,-19,39:18
-3,-18,39:18
-3,-17,39:18
-3,-16,39:18
-3,-15,39:18
-3,-14,39:18
-3,-13,39:18
-3,-12,39:18
-3,-11,39:18
-3,-10,39:18
-3,-9,39:18
-3,-8,39:18
-3,-7,39:18
-3,-6,39:18
-3,-5,39:18
-3,-4,39:18
-3,-3,39:18
-3,-2,39:18
-3,-1,39:18
-3,0,39:18
-3,1,39:18
-3,2,39:18
-3,3,39:18
-3,4,39:18
-3,5,39:18
-3,6,39:18
-3,7,39:18
-3,8,39:18
-3,9,39:18
-3,10,39:18
-3,11,39:18
-3,12,39:18
-3,13,39:18
-3,14,39:18
-3,15,39:18
-3,16,39:18
-2,-21,39:18
-2,-20,39:18
-2,-19,39:18
-2,-18,39:18
-2,-17,39:18
-2,-16,39:18
-2,-15,39:18
-2,-14,39:18
-2,-13,39:18
-2,-12,39:18
-2,-11,39:18
-2,-10,39:18
-2,-9,39:18
-2,-8,39:18
-2,-7,39:18
-2,-6,39:18
-2,-5,39:18
-2,-4,39:18
-2,-3,39:18
-2,-2,39:18
-2,-1,39:18
-2,0,39:18
-2,1,39:18
-2,2,39:18
-2,3,39:18
-2,4,39:18
-2,5,39:18
-2,6,39:18
-2,7,39:18
-2,8,39:18
-2,9,39:18
-2,10,39:18
-2,11,39:18
-2,12,39:18
-2,13,39:18
-2,14,39:18
-2,15,39:18
-2,16,39:18
-2,17,39:18
-1,-22,39:18
-1,-21,39:18
-1,-20,39:18
-1,-19,39:18
-1,-18,39:18
-1,-17,39:18
-1,-16,39:18
-1,-15,39:18
-1,-14,39:18
-1,-13,39:18
-1,-12,39:18
-1,-11,39:18
-1,-10,39:18
-1,-9,39:18
-1,-8,39:18
-1,-7,39:18
-1,-6,39:18
-1,-5,39:18
-1,-4,39:18
-1,-3,39:18
-1,-2,39:18
-1,-1,39:18
-1,0,39:18
-1,1,39:18
-1,2,39:18
-1,3,39:18
-1,4,39:18
-1,5,39:18
-1,6,39:18
-1,7,39:18
-1,8,39:18
-1,9,39:18
-1,10,39:18
-1,11,39:18
-1,12,39:18
-1,13,39:18
-1,14,39:18
-1,15,39:18
-1,16,39:18
-1,17,39:18
-1,18,39:18
0,-23,39:18
0,-22,39:18
0,-21,39:18
0,-20,39:18
0,-19,39:18
0,-18,39:18
0,-17,39:18
0,-16,39:18
0,-15,39:18
0,-14,39:18
0,-13,39:18
0,-12,39:18
0,-11,39:18
0,-10,39:18
0,-9,39:18
0,-8,39:18
0,-7,39:18
0,-6,39:18
0,-5,39:18
0,-4,39:18
0,-3,39:18
0,-2,39:18
0,-1,39:18
0,0,39:18
0,1,39:18
0,2,39:18
0,3,39:18
0,4,39:18
0,5,39:18
0,6,39:18
0,7,39:18
0,8,39:18
0,9,39:18
0,10,39:18
0,11,39:18
0,12,39:18
0,13,39:18
0,14,39:18
0,15,39:18
0,16,39:18
0,17,39:18
0,18,39:18
1,-23,39:18
1,-22,39:18
1,-21,39:18
1,-20,39:18
1,-19,39:18
1,-18,39:18
1,-17,39:18
1,-16,39:18
1,-15,39:18
1,-14,39:18
1,-13,39:18
1,-12,39:18
1,-11,39:18
1,-10,39:18
1,-9,39:18
1,-8,39:18
1,-7,39:18
1,-6,39:18
1,-5,39:18
1,-4,39:18
1,-3,39:18
1,-2,39:18
1,-1,39:18
1,0,39:18
1,1,39:18
1,2,39:18
1,3,39:18
1,4,39:18
1,5,39:18
1,6,39:18
1,7,39:18
1,8,39:18
1,9,39:18
1,10,39:18
1,11,39:18
1,12,39:18
1,13,39:18
1,14,39:18
1,15,39:18
1,16,39:18
1,17,39:18
1,18,39:18
2,-24,39:18
2,-23,39:18
2,-22,39:18
2,-21,39:18
2,-20,39:18
2,-19,39:18
2,-18,39:18
2,-17,39:18
2,-16,39:18
2,-15,39:18
2,-14,39:18
2,-13,39:18
2,-12,39:18
2,-11,39:18
2,-10,39:18
2,-9,39:18
2,-8,39:18
2,-7,39:18
2,-6,39:18
2,-5,39:18
2,-4,39:18
2,-3,39:18
2,-2,39:18
2,-1,39:18
2,0,39:18
2,1,39:18
2,2,39:18
2,3,39:18
2,4,39:18
2,5,39:18
2,6,39:18
2,7,39:18
2,8,39:18
2,9,39:18
2,10,39:18
2,11,39:18
2,12,39:18
2,13,39:18
2,14,39:18
2,15,39:18
2,16,39:18
2,17,39:18
2,18,39:18
3,-24,39:18
3,-23,39:18
3,-22,39:18
3,-21,39:18
3,-20,39:18
3,-19,39:18
3,-18,39:18
3,-17,39:18
3,-16,39:18
3,-15,39:18
3,-14,39:18
3,-13,39:18
3,-12,39:18
3,-11,39:18
3,-10,39:18
3,-9,39:18
3,-8,39:18
3,-7,39:18
3,-6,39:18
3,-5,39:18
3,-4,39:18
3,-3,39:18
3,-2,39:18
3,-1,39:18
3,0,39:18
3,1,39:18
3,2,39:18
3,3,39:18
3,4,39:18
3,5,39:18
3,6,39:18
3,7,39:18
3,8,39:18
3,9,39:18
3,10,39:18
3,11,39:18
3,12,39:18
3,13,39:18
3,14,39:18
3,15,39:18
3,16,39:18
3,17,39:18
3,18,39:18
3,19,39:18
4,-24,39:18
4,-23,39:18
4,-22,39:18
4,-21,39:18
4,-20,39:18
4,-19,39:18
4,-18,39:18
4,-17,39:18
4,-16,39:18
4,-15,39:18
4,-14,39:18
4,-13,39:18
4,-12,39:18
4,-11,39:18
4,-10,39:18
4,-9,39:18
4,-8,39:18
4,-7,39:18
4,-6,39:18
4,-5,39:18
4,-4,39:18
4,-3,39:18
4,-2,39:18
4,-1,39:18
4,0,39:18
4,1,39:18
4,2,39:18
4,3,39:18
4,4,39:18
4,5,39:18
4,6,39:18
4,7,39:18
4,8,39:18
4,9,39:18
4,10,39:18
4,11,39:18
4,12,39:18
4,13,39:18
4,14,39:18
4,15,39:18
4,16,39:18
4,17,39:18
4,18,39:18
4,19,39:18
5,-24,39:18
5,-23,39:18
5,-22,39:18
5,-21,39:18
5,-20,39:18
5,-19,39:18
5,-18,39:18
5,-17,39:18
5,-16,39:18
5,-15,39:18
5,-14,39:18
5,-13,39:18
5,-12,39:18
5,-11,39:18
5,-10,39:18
5,-9,39:18
5,-8,39:18
5,-7,39:18
5,-6,39:18
5,-5,39:18
5,-4,39:18
5,-3,39:18
5,-2,39:18
5,-1,39:18
5,0,39:18
5,1,39:18
5,2,39:18
5,3,39:18
5,4,39:18
5,5,39:18
5,6,39:18
5,7,39:18
5,8,39:18
5,9,39:18
5,10,39:18
5,11,39:18
5,12,39:18
5,13,39:18
5,14,39:18
5,15,39:18
5,16,39:18
5,17,39:18
5,18,39:18
5,19,39:18
6,-23,39:18
6,-22,39:18
6,-21,39:18
6,-20,39:18
6,-19,39:18
6,-18,39:18
6,-17,39:18
6,-16,39:18
6,-15,39:18
6,-14,39:18
6,-13,39:18
6,-12,39:18
6,-11,39:18
6,-10,39:18
6,-9,39:18
6,-8,39:18
6,-7,39:18
6,-6,39:18
6,-5,39:18
6,-4,39:18
6,-3,39:18
6,-2,39:18
6,-1,39:18
6,0,39:18
6,1,39:18
6,2,39:18
6,3,39:18
6,4,39:18
6,5,39:18
6,6,39:18
6,7,39:18
6,8,39:18
6,9,39:18
6,10,39:18
6,11,39:18
6,12,39:18
6,13,39:18
6,14,39:18
6,15,39:18
6,16,39:18
6,17,39:18
6,18,39:18
6,19,39:18
7,-23,39:18
7,-22,39:18
7,-21,39:18
7,-20,39:18
7,-19,39:18
7,-18,39:18
7,-17,39:18
7,-16,39:18
7,-15,39:18
7,-14,39:18
7,-13,39:18
7,-12,39:18
7,-11,39:18
7,-10,39:18
7,-9,39:18
7,-8,39:18
7,-7,39:18
7,-6,39:18
7,-5,39:18
7,-4,39:18
7,-3,39:18
7,-2,39:18
7,-1,39:18
7,0,39:18
7,1,39:18
7,2,39:18
7,3,39:18
7,4,39:18
7,5,39:18
7,6,39:18
7,7,39:18
7,8,39:18
7,9,39:18
7,10,39:18
7,11,39:18
7,12,39:18
7,13,39:18
7,14,39:18
7,15,39:18
7,16,39:18
7,17,39:18
7,18,39:18
8,-22,39:18
8,-21,39:18
8,-20,39:18
8,-19,39:18
8,-18,39:18
8,-17,39:18
8,-16,39:18
8,-15,39:18
8,-14,39:18
8,-13,39:18
8,-12,39:18
8,-11,39:18
8,-10,39:18
8,-9,39:18
8,-8,39:18
8,-7,39:18
8,-6,39:18
8,-5,39:18
8,-4,39:18
8,-3,39:18
8,-2,39:18
8,-1,39:18
8,0,39:18
8,1,39:18
8,2,39:18
8,3,39:18
8,4,39:18
8,5,39:18
8,6,39:18
8,7,39:18
8,8,39:18
8,9,39:18
8,10,39:18
8,11,39:18
8,12,39:18
8,13,39:18
8,14,39:18
8,15,39:18
8,16,39:18
8,17,39:18
9,-21,39:18
9,-20,39:18
9,-19,39:18
9,-18,39:18
9,-17,39:18
9,-16,39:18
9,-15,39:18
9,-14,39:18
9,-13,39:18
9,-12,39:18
9,-11,39:18
9,-10,39:18
9,-9,39:18
9,-8,39:18
9,-7,39:18
9,-6,39:18
9,-5,39:18
9,-4,39:18
9,-3,39:18
9,-2,39:18
9,-1,39:18
9,0,39:18
9,1,39:18
9,2,39:18
9,3,39:18
9,4,39:18
9,5,39:18
9,6,39:18
9,7,39:18
9,8,39:18
9,9,39:18
9,10,39:18
9,11,39:18
9,12,39:18
9,13,39:18
9,14,39:18
9,15,39:18
9,16,39:18
10,-21,39:18
10,-20,39:18
10,-19,39:18
10,-18,39:18
10,-17,39:18
10,-16,39:18
10,-15,39:18
10,-14,39:18
10,-13,39:18
10,-12,39:18
10,-11,39:18
10,-10,39:18
10,-9,39:18
10,-8,39:18
10,-7,39:18
10,-6,39:18
10,-5,39:18
10,-4,39:18
10,-3,39:18
10,-2,39:18
10,-1,39:18
10,0,39:18
10,1,39:18
10,2,39:18
10,3,39:18
10,4,39:18
10,5,39:18
10,6,39:18
10,7,39:18
10,8,39:18
10,9,39:18
10,10,39:18
10,11,39:18
10,12,39:18
10,13,39:18
10,14,39:18
10,15,39:18
10,16,39:18
11,-20,39:18
11,-19,39:18
11,-18,39:18
11,-17,39:18
11,-16,39:18
11,-15,39:18
11,-14,39:18
11,-13,39:18
11,-12,39:18
11,-11,39:18
11,-10,39:18
11,-9,39:18
11,-8,39:18
11,-7,39:18
11,-6,39:18
11,-5,39:18
11,-4,39:18
11,-3,39:18
11,-2,39:18
11,-1,39:18
11,0,39:18
11,1,39:18
11,2,39:18
11,3,39:18
11,4,39:18
11,5,39:18
11,6,39:18
11,7,39:18
11,8,39:18
11,9,39:18
11,10,39:18
11,11,39:18
11,12,39:18
11,13,39:18
11,14,39:18
11,15,39:18
12,-20,39:18
12,-19,39:18
12,-18,39:18
12,-17,39:18
12,-16,39:18
12,-15,39:18
12,-14,39:18
12,-13,39:18
12,-12,39:18
12,-11,39:18
12,-10,39:18
12,-9,39:18
12,-8,39:18
12,-7,39:18
12,-6,39:18
12,-5,39:18
12,-4,39:18
12,-3,39:18
12,-2,39:18
12,-1,39:18
12,0,39:18
12,1,39:18
12,2,39:18
12,3,39:18
12,4,39:18
12,5,39:18
12,6,39:18
12,7,39:18
12,8,39:18
12,9,39:18
12,10,39:18
12,11,39:18
12,12,39:18
12,13,39:18
12,14,39:18
12,15,39:18
13,-19,39:18
13,-18,39:18
13,-17,39:18
13,-16,39:18
13,-15,39:18
13,-14,39:18
13,-13,39:18
13,-12,39:18
13,-11,39:18
13,-10,39:18
13,-9,39:18
13,-8,39:18
13,-7,39:18
13,-6,39:18
13,-5,39:18
13,-4,39:18
13,-3,39:18
13,-2,39:18
13,-1,39:18
13,0,39:18
13,1,39:18
13,2,39:18
13,3,39:18
13,4,39:18
13,5,39:18
13,6,39:18
13,7,39:18
13,8,39:18
13,9,39:18
13,10,39:18
13,11,39:18
13,12,39:18
13,13,39:18
13,14,39:18
13,15,39:18
14,-19,39:18
14,-18,39:18
14,-17,39:18
14,-16,39:18
14,-15,39:18
14,-14,39:18
14,-13,39:18
14,-12,39:18
14,-11,39:18
14,-10,39:18
14,-9,39:18
14,-8,39:18
14,-7,39:18
14,-6,39:18
14,-5,39:18
14,-4,39:18
14,-3,39:18
14,-2,39:18
14,-1,39:18
14,0,39:18
14,1,39:18
14,2,39:18
14,3,39:18
14,4,39:18
14,5,39:18
14,6,39:18
14,7,39:18
14,8,39:18
14,9,39:18
14,10,39:18
14,11,39:18
14,12,39:18
14,13,39:18
14,14,39:18
14,15,39:18
15,-18,39:18
15,-17,39:18
15,-16,39:18
15,-15,39:18
15,-14,39:18
15,-13,39:18
15,-12,39:18
15,-11,39:18
15,-10,39:18
15,-9,39:18
15,-8,39:18
15,-7,39:18
15,-6,39:18
15,-5,39:18
15,-4,39:18
15,-3,39:18
15,-2,39:18
15,-1,39:18
15,0,39:18
15,1,39:18
15,2,39:18
15,3,39:18
15,4,39:18
15,5,39:18
15,6,39:18
15,7,39:18
15,8,39:18
15,9,39:18
15,10,39:18
15,11,39:18
15,12,39:18
15,13,39:18
15,14,39:18
16,-18,39:18
16,-17,39:18
16,-16,39:18
16,-15,39:18
16,-14,39:18
16,-13,39:18
16,-12,39:18
16,-11,39:18
16,-10,39:18
16,-9,39:18
16,-8,39:18
16,-7,39:18
16,-6,39:18
16,-5,39:18
16,-4,39:18
16,-3,39:18
16,-2,39:18
16,-1,39:18
16,0,39:18
16,1,39:18
16,2,39:18
16,3,39:18
16,4,39:18
16,5,39:18
16,6,39:18
16,7,39:18
16,8,39:18
16,9,39:18
16,10,39:18
16,11,39:18
16,12,39:18
16,13,39:18
17,-17,39:18
17,-16,39:18
17,-15,39:18
17,-14,39:18
17,-13,39:18
17,-12,39:18
17,-11,39:18
17,-10,39:18
17,-9,39:18
17,-8,39:18
17,-7,39:18
17,-6,39:18
17,-5,39:18
17,-4,39:18
17,-3,39:18
17,-2,39:18
17,-1,39:18
17,0,39:18
17,1,39:18
17,2,39:18
17,3,39:18
17,4,39:18
17,5,39:18
17,6,39:18
17,7,39:18
17,8,39:18
17,9,39:18
17,10,39:18
17,11,39:18
17,12,39:18
18,-14,39:18
18,-13,39:18
18,-12,39:18
18,-11,39:18
18,-10,39:18
18,-9,39:18
18,-8,39:18
18,-7,39:18
18,-6,39:18
18,-5,39:18
18,-4,39:18
18,-3,39:18
18,-2,39:18
18,-1,39:18
18,0,39:18
18,1,39:18
18,2,39:18
18,3,39:18
18,4,39:18
18,5,39:18
18,6,39:18
18,7,39:18
18,8,39:18
18,9,39:18
18,10,39:18
18,11,39:18
18,12,39:18
19,-12,39:18
19,-11,39:18
19,-10,39:18
19,-9,39:18
19,-8,39:18
19,-7,39:18
19,-6,39:18
19,-5,39:18
19,-4,39:18
19,-3,39:18
19,-2,39:18
19,-1,39:18
19,0,39:18
19,1,39:18
19,2,39:18
19,3,39:18
19,4,39:18
19,5,39:18
19,6,39:18
19,7,39:18
19,8,39:18
19,9,39:18
19,10,39:18
19,11,39:18
20,-11,39:18
20,-10,39:18
20,-9,39:18
20,-8,39:18
20,-7,39:18
20,-6,39:18
20,-5,39:18
20,-4,39:18
20,-3,39:18
20,-2,39:18
20,-1,39:18
20,0,39:18
20,1,39:18
20,2,39:18
20,3,39:18
20,4,39:18
20,5,39:18
20,6,39:18
20,7,39:18
20,8,39:18
20,9,39:18
20,10,39:18
21,-9,39:18
21,-8,39:18
21,-7,39:18
21,-6,39:18
21,-5,39:18
21,-4,39:18
21,-3,39:18
21,-2,39:18
21,-1,39:18
21,0,39:18
21,1,39:18
21,2,39:18
21,3,39:18
21,4,39:18
21,5,39:18
21,6,39:18
21,7,39:18
21,8,39:18
21,9,39:18
22,-4,39:18
22,-3,39:18
22,-2,39:18
22,-1,39:18
22,0,39:18
22,1,39:18
22,2,39:18
22,3,39:18
22,4,39:18
22,5,39:18
22,6,39:18
22,7,39:18
22,8,39:18
23,-2,39:18
23,-1,39:18
23,0,39:18
23,1,39:18
23,2,39:18
23,3,39:18
23,4,39:18
23,5,39:18
24,-1,39:18
24,0,39:18
24,1,39:18
24,2,39:18
24,3,39:18
-18,-7,40:18
-18,-6,40:18
-18,-5,40:18
-18,-4,40:18
-18,-3,40:18
-18,1,40:18
-18,2,40:18
-17,-10,40:18
-17,-9,40:18
-17,-8,40:18
-17,-7,40:18
-17,-6,40:18
-17,-5,40:18
-17,-4,40:18
-17,-3,40:18
-17,-2,40:18
-17,-1,40:18
-17,0,40:18
-17,1,40:18
-17,2,40:18
-17,3,40:18
-17,4,40:18
-17,6,40:18
-16,-12,40:18
-16,-11,40:18
-16,-10,40:18
-16,-9,40:18
-16,-8,40:18
-16,-7,40:18
-16,-6,40:18
-16,-5,40:18
-16,-4,40:18
-16,-3,40:18
-16,-2,40:18
-16,-1,40:18
-16,0,40:18
-16,1,40:18
-16,2,40:18
-16,3,40:18
-16,4,40:18
-16,5,40:18
-16,6,40:18
-16,7,40:18
-16,8,40:18
-15,-13,40:18
-15,-12,40:18
-15,-11,40:18
-15,-10,40:18
-15,-9,40:18
-15,-8,40:18
-15,-7,40:18
-15,-6,40:18
-15,-5,40:18
-15,-4,40:18
-15,-3,40:18
-15,-2,40:18
-15,-1,40:18
-15,0,40:18
-15,1,40:18
-15,2,40:18
-15,3,40:18
-15,4,40:18
-15,5,40:18
-15,6,40:18
-15,7,40:18
-15,8,40:18
-15,9,40:18
-14,-14,40:18
-14,-13,40:18
-14,-12,40:18
-14,-11,40:18
-14,-10,40:18
-14,-9,40:18
-14,-8,40:18
-14,-7,40:18
-14,-6,40:18
-14,-5,40:18
-14,-4,40:18
-14,-3,40:18
-14,-2,40:18
-14,-1,40:18
-14,0,40:18
-14,1,40:18
-14,2,40:18
-14,3,40:18
-14,4,40:18
-14,5,40:18
-14,6,40:18
-14,7,40:18
-14,8,40:18
-14,9,40:18
-14,10,40:18
-13,-15,40:18
-13,-14,40:18
-13,-13,40:18
-13,-12,40:18
-13,-11,40:18
-13,-10,40:18
-13,-9,40:18
-13,-8,40:18
-13,-7,40:18
-13,-6,40:18
-13,-5,40:18
-13,-4,40:18
-13,-3,40:18
-13,-2,40:18
-13,-1,40:18
-13,0,40:18
-13,1,40:18
-13,2,40:18
-13,3,40:18
-13,4,40:18
-13,5,40:18
-13,6,40:18
-13,7,40:18
-13,8,40:18
-13,9,40:18
-13,10,40:18
-13,11,40:18
-12,-16,40:18
-12,-15,40:18
-12,-14,40:18
-12,-13,40:18
-12,-12,40:18
-12,-11,40:18
-12,-10,40:18
-12,-9,40:18
-12,-8,40:18
-12,-7,40:18
-12,-6,40:18
-12,-5,40:18
-12,-4,40:18
-12,-3,40:18
-12,-2,40:18
-12,-1,40:18
-12,0,40:18
-12,1,40:18
-12,2,40:18
-12,3,40:18
-12,4,40:18
-12,5,40:18
-12,6,40:18
-12,7,40:18
-12,8,40:18
-12,9,40:18
-12,10,40:18
-12,11,40:18
-12,12,40:18
-11,-17,40:18
-11,-16,40:18
-11,-15,40:18
-11,-14,40:18
-11,-13,40:18
-11,-12,40:18
-11,-11,40:18
-11,-10,40:18
-11,-9,40:18
-11,-8,40:18
-11,-7,40:18
-11,-6,40:18
-11,-5,40:18
-11,-4,40:18
-11,-3,40:18
-11,-2,40:18
-11,-1,40:18
-11,0,40:18
-11,1,40:18
-11,2,40:18
-11,3,40:18
-11,4,40:18
-11,5,40:18
-11,6,40:18
-11,7,40:18
-11,8,40:18
-11,9,40:18
-11,10,40:18
-11,11,40:18
-11,12,40:18
-11,13,40:18
-10,-18,40:18
-10,-17,40:18
-10,-16,40:18
-10,-15,40:18
-10,-14,40:18
-10,-13,40:18
-10,-12,40:18
-10,-11,40:18
-10,-10,40:18
-10,-9,40:18
-10,-8,40:18
-10,-7,40:18
-10,-6,40:18
-10,-5,40:18
-10,-4,40:18
-10,-3,40:18
-10,-2,40:18
-10,-1,40:18
-10,0,40:18
-10,1,40:18
-10,2,40:18
-10,3,40:18
-10,4,40:18
-10,5,40:18
-10,6,40:18
-10,7,40:18
-10,8,40:18
-10,9,40:18
-10,10,40:18
-10,11,40:18
-10,12,40:18
-10,13,40:18
-10,14,40:18
-9,-19,40:18
-9,-18,40:18
-9,-17,40:18
-9,-16,40:18
-9,-15,40:18
-9,-14,40:18
-9,-13,40:18
-9,-12,40:18
-9,-11,40:18
-9,-10,40:18
-9,-9,40:18
-9,-8,40:18
-9,-7,40:18
-9,-6,40:18
-9,-5,40:18
-9,-4,40:18
-9,-3,40:18
-9,-2,40:18
-9,-1,40:18
-9,0,40:18
-9,1,40:18
-9,2,40:18
-9,3,40:18
-9,4,40:18
-9,5,40:18
-9,6,40:18
-9,7,40:18
-9,8,40:18
-9,9,40:18
-9,10,40:18
-9,11,40:18
-9,12,40:18
-9,13,40:18
-9,14,40:18
-9,15,40:18
-8,-19,40:18
-8,-18,40:18
-8,-17,40:18
-8,-16,40:18
-8,-15,40:18
-8,-14,40:18
-8,-13,40:18
-8,-12,40:18
-8,-11,40:18
-8,-10,40:18
-8,-9,40:18
-8,-8,40:18
-8,-7,40:18
-8,-6,40:18
-8,-5,40:18
-8,-4,40:18
-8,-3,40:18
-8,-2,40:18
-8,-1,40:18
-8,0,40:18
-8,1,40:18
-8,2,40:18
-8,3,40:18
-8,4,40:18
-8,5,40:18
-8,6,40:18
-8,7,40:18
-8,8,40:18
-8,9,40:18
-8,10,40:18
-8,11,40:18
-8,12,40:18
-8,13,40:18
-8,14,40:18
-8,15,40:18
-7,-20,40:18
-7,-19,40:18
-7,-18,40:18
-7,-17,40:18
-7,-16,40:18
-7,-15,40:18
-7,-14,40:18
-7,-13,40:18
-7,-12,40:18
-7,-11,40:18
-7,-10,40:18
-7,-9,40:18
-7,-8,40:18
-7,-7,40:18
-7,-6,40:18
-7,-5,40:18
-7,-4,40:18
-7,-3,40:18
-7,-2,40:18
-7,-1,40:18
-7,0,40:18
-7,1,40:18
-7,2,40:18
-7,3,40:18
-7,4,40:18
-7,5,40:18
-7,6,40:18
-7,7,40:18
-7,8,40:18
-7,9,40:18
-7,10,40:18
-7,11,40:18
-7,12,40:18
-7,13,40:18
-7,14,40:18
-7,15,40:18
-7,16,40:18
-6,-20,40:18
-6,-19,40:18
-6,-18,40:18
-6,-17,40:18
-6,-16,40:18
-6,-15,40:18
-6,-14,40:18
-6,-13,40:18
-6,-12,40:18
-6,-11,40:18
-6,-10,40:18
-6,-9,40:18
-6,-8,40:18
-6,-7,40:18
-6,-6,40:18
-6,-5,40:18
-6,-4,40:18
-6,-3,40:18
-6,-2,40:18
-6,-1,40:18
-6,0,40:18
-6,1,40:18
-6,2,40:18
-6,3,40:18
-6,4,40:18
-6,5,40:18
-6,6,40:18
-6,7,40:18
-6,8,40:18
-6,9,40:18
-6,10,40:18
-6,11,40:18
-6,12,40:18
-6,13,40:18
-6,14,40:18
-6,15,40:18
-6,16,40:18
-5,-21,40:18
-5,-20,40:18
-5,-19,40:18
-5,-18,40:18
-5,-17,40:18
-5,-16,40:18
-5,-15,40:18
-5,-14,40:18
-5,-13,40:18
-5,-12,40:18
-5,-11,40:18
-5,-10,40:18
-5,-9,40:18
-5,-8,40:18
-5,-7,40:18
-5,-6,40:18
-5,-5,40:18
-5,-4,40:18
-5,-3,40:18
-5,-2,40:18
-5,-1,40:18
-5,0,40:18
-5,1,40:18
-5,2,40:18
-5,3,40:18
-5,4,40:18
-5,5,40:18
-5,6,40:18
-5,7,40:18
-5,8,40:18
-5,9,40:18
-5,10,40:18
-5,11,40:18
-5,12,40:18
-5,13,40:18
-5,14,40:18
-5,15,40:18
-5,16,40:18
-5,17,40:18
-4,-21,40:18
-4,-20,40:18
-4,-19,40:18
-4,-18,40:18
-4,-17,40:18
-4,-16,40:18
-4,-15,40:18
-4,-14,40:18
-4,-13,40:18
-4,-12,40:18
-4,-11,40:18
-4,-10,40:18
-4,-9,40:18
-4,-8,40:18
-4,-7,40:18
-4,-6,40:18
-4,-5,40:18
-4,-4,40:18
-4,-3,40:18
-4,-2,40:18
-4,-1,40:18
-4,0,40:18
-4,1,40:18
-4,2,40:18
-4,3,40:18
-4,4,40:18
-4,5,40:18
-4,6,40:18
-4,7,40:18
-4,8,40:18
-4,9,40:18
-4,10,40:18
-4,11,40:18
-4,12,40:18
-4,13,40:18
-4,14,40:18
-4,15,40:18
-4,16,40:18
-4,17,40:18
-3,-21,40:18
-3,-20,40:18
-3,-19,40:18
-3,-18,40:18
-3,-17,40:18
-3,-16,40:18
-3,-15,40:18
-3,-14,40:18
-3,-13,40:18
-3,-12,40:18
-3,-11,40:18
-3,-10,40:18
-3,-9,40:18
-3,-8,40:18
-3,-7,40:18
-3,-6,40:18
-3,-5,40:18
-3,-4,40:18
-3,-3,40:18
-3,-2,40:18
-3,-1,40:18
-3,0,40:18
-3,1,40:18
-3,2,40:18
-3,3,40:18
-3,4,40:18
-3,5,40:18
-3,6,40:18
-3,7,40:18
-3,8,40:18
-3,9,40:18
-3,10,40:18
-3,11,40:18
-3,12,40:18
-3,13,40:18
-3,14,40:18
-3,15,40:18
-3,16,40:18
-3,17,40:18
-2,-22,40:18
-2,-21,40:18
-2,-20,40:18
-2,-19,40:18
-2,-18,40:18
-2,-17,40:18
-2,-16,40:18
-2,-15,40:18
-2,-14,40:18
-2,-13,40:18
-2,-12,40:18
-2,-11,40:18
-2,-10,40:18
-2,-9,40:18
-2,-8,40:18
-2,-7,40:18
-2,-6,40:18
-2,-5,40:18
-2,-4,40:18
-2,-3,40:18
-2,-2,40:18
-2,-1,40:18
-2,0,40:18
-2,1,40:18
-2,2,40:18
-2,3,40:18
-2,4,40:18
-2,5,40:18
-2,6,40:18
-2,7,40:18
-2,8,40:18
-2,9,40:18
-2,10,40:18
-2,11,40:18
-2,12,40:18
-2,13,40:18
-2,14,40:18
-2,15,40:18
-2,16,40:18
-2,17,40:18
-2,18,40:18
-1,-23,40:18
-1,-22,40:18
-1,-21,40:18
-1,-20,40:18
-1,-19,40:18
-1,-18,40:18
-1,-17,40:18
-1,-16,40:18
-1,-15,40:18
-1,-14,40:18
-1,-13,40:18
-1,-12,40:18
-1,-11,40:18
-1,-10,40:18
-1,-9,40:18
-1,-8,40:18
-1,-7,40:18
-1,-6,40:18
-1,-5,40:18
-1,-4,40:18
-1,-3,40:18
-1,-2,40:18
-1,-1,40:18
-1,0,40:18
-1,1,40:18
-1,2,40:18
-1,3,40:18
-1,4,40:18
-1,5,40:18
-1,6,40:18
-1,7,40:18
-1,8,40:18
-1,9,40:18
-1,10,40:18
-1,11,40:18
-1,12,40:18
-1,13,40:18
-1,14,40:18
-1,15,40:18
-1,16,40:18
-1,17,40:18
-1,18,40:18
-1,19,40:18
0,-24,40:18
0,-23,40:18
0,-22,40:18
0,-21,40:18
0,-20,40:18
0,-19,40:18
0,-18,40:18
0,-17,40:18
0,-16,40:18
0,-15,40:18
0,-14,40:18
0,-13,40:18
0,-12,40:18
0,-11,40:18
0,-10,40:18
0,-9,40:18
0,-8,40:18
0,-7,40:18
0,-6,40:18
0,-5,40:18
0,-4,40:18
0,-3,40:18
0,-2,40:18
0,-1,40:18
0,0,40:18
0,1,40:18
0,2,40:18
0,3,40:18
0,4,40:18
0,5,40:18
0,6,40:18
0,7,40:18
0,8,40:18
0,9,40:18
0,10,40:18
0,11,40:18
0,12,40:18
0,13,40:18
0,14,40:18
0,15,40:18
0,16,40:18
0,17,40:18
0,18,40:18
0,19,40:18
1,-24,40:18
1,-23,40:18
1,-22,40:18
1,-21,40:18
1,-20,40:18
1,-19,40:18
1,-18,40:18
1,-17,40:18
1,-16,40:18
1,-15,40:18
1,-14,40:18
1,-13,40:18
1,-12,40:18
1,-11,40:18
1,-10,40:18
1,-9,40:18
1,-8,40:18
1,-7,40:18
1,-6,40:18
1,-5,40:18
1,-4,40:18
1,-3,40:18
1,-2,40:18
1,-1,40:18
1,0,40:18
1,1,40:18
1,2,40:18
1,3,40:18
1,4,40:18
1,5,40:18
1,6,40:18
1,7,40:18
1,8,40:18
1,9,40:18
1,10,40:18
1,11,40:18
1,12,40:18
1,13,40:18
1,14,40:18
1,15,40:18
1,16,40:18
1,17,40:18
1,18,40:18
1,19,40:18
2,-25,40:18
2,-24,40:18
2,-23,40:18
2,-22,40:18
2,-21,40:18
2,-20,40:18
2,-19,40:18
2,-18,40:18
2,-17,40:18
2,-16,40:18
2,-15,40:18
2,-14,40:18
2,-13,40:18
2,-12,40:18
2,-11,40:18
2,-10,40:18
2,-9,40:18
2,-8,40:18
2,-7,40:18
2,-6,40:18
2,-5,40:18
2,-4,40:18
2,-3,40:18
2,-2,40:18
2,-1,40:18
2,0,40:18
2,1,40:18
2,2,40:18
2,3,40:18
2,4,40:18
2,5,40:18
2,6,40:18
2,7,40:18
2,8,40:18
2,9,40:18
2,10,40:18
2,11,40:18
2,12,40:18
2,13,40:18
2,14,40:18
2,15,40:18
2,16,40:18
2,17,40:18
2,18,40:18
2,19,40:18
3,-25,40:18
3,-24,40:18
3,-23,40:18
3,-22,40:18
3,-21,40:18
3,-20,40:18
3,-19,40:18
3,-18,40:18
3,-17,40:18
3,-16,40:18
3,-15,40:18
3,-14,40:18
3,-13,40:18
3,-12,40:18
3,-11,40:18
3,-10,40:18
3,-9,40:18
3,-8,40:18
3,-7,40:18
3,-6,40:18
3,-5,40:18
3,-4,40:18
3,-3,40:18
3,-2,40:18
3,-1,40:18
3,0,40:18
3,1,40:18
3,2,40:18
3,3,40:18
3,4,40:18
3,5,40:18
3,6,40:18
3,7,40:18
3,8,40:18
3,9,40:18
3,10,40:18
3,11,40:18
3,12,40:18
3,13,40:18
3,14,40:18
3,15,40:18
3,16,40:18
3,17,40:18
3,18,40:18
3,19,40:18
3,20,40:18
4,-25,40:18
4,-24,40:18
4,-23,40:18
4,-22,40:18
4,-21,40:18
4,-20,40:18
4,-19,40:18
4,-18,40:18
4,-17,40:18
4,-16,40:18
4,-15,40:18
4,-14,40:18
4,-13,40:18
4,-12,40:18
4,-11,40:18
4,-10,40:18
4,-9,40:18
4,-8,40:18
4,-7,40:18
4,-6,40:18
4,-5,40:18
4,-4,40:18
4,-3,40:18
4,-2,40:18
4,-1,40:18
4,0,40:18
4,1,40:18
4,2,40:18
4,3,40:18
4,4,40:18
4,5,40:18
4,6,40:18
4,7,40:18
4,8,40:18
4,9,40:18
4,10,40:18
4,11,40:18
4,12,40:18
4,13,40:18
4,14,40:18
4,15,40:18
4,16,40:18
4,17,40:18
4,18,40:18
4,19,40:18
4,20,40:18
5,-25,40:18
5,-24,40:18
5,-23,40:18
5,-22,40:18
5,-21,40:18
5,-20,40:18
5,-19,40:18
5,-18,40:18
5,-17,40:18
5,-16,40:18
5,-15,40:18
5,-14,40:18
5,-13,40:18
5,-12,40:18
5,-11,40:18
5,-10,40:18
5,-9,40:18
5,-8,40:18
5,-7,40:18
5,-6,40:18
5,-5,40:18
5,-4,40:18
5,-3,40:18
5,-2,40:18
5,-1,40:18
5,0,40:18
5,1,40:18
5,2,40:18
5,3,40:18
5,4,40:18
5,5,40:18
5,6,40:18
5,7,40:18
5,8,40:18
5,9,40:18
5,10,40:18
5,11,40:18
5,12,40:18
5,13,40:18
5,14,40:18
5,15,40:18
5,16,40:18
5,17,40:18
5,18,40:18
5,19,40:18
5,20,40:18
6,-24,40:18
6,-23,40:18
6,-22,40:18
6,-21,40:18
6,-20,40:18
6,-19,40:18
6,-18,40:18
6,-17,40:18
6,-16,40:18
6,-15,40:18
6,-14,40:18
6,-13,40:18
6,-12,40:18
6,-11,40:18
6,-10,40:18
6,-9,40:18
6,-8,40:18
6,-7,40:18
6,-6,40:18
6,-5,40:18
6,-4,40:18
6,-3,40:18
6,-2,40:18
6,-1,40:18
6,0,40:18
6,1,40:18
6,2,40:18
6,3,40:18
6,4,40:18
6,5,40:18
6,6,40:18
6,7,40:18
6,8,40:18
6,9,40:18
6,10,40:18
6,11,40:18
6,12,40:18
6,13,40:18
6,14,40:18
6,15,40:18
6,16,40:18
6,17,40:18
6,18,40:18
6,19,40:18
6,20,40:18
7,-24,40:18
7,-23,40:18
7,-22,40:18
7,-21,40:18
7,-20,40:18
7,-19,40:18
7,-18,40:18
7,-17,40:18
7,-16,40:18
7,-15,40:18
7,-14,40:18
7,-13,40:18
7,-12,40:18
7,-11,40:18
7,-10,40:18
7,-9,40:18
7,-8,40:18
7,-7,40:18
7,-6,40:18
7,-5,40:18
7,-4,40:18
7,-3,40:18
7,-2,40:18
7,-1,40:18
7,0,40:18
7,1,40:18
7,2,40:18
7,3,40:18
7,4,40:18
7,5,40:18
7,6,40:18
7,7,40:18
7,8,40:18
7,9,40:18
7,10,40:18
7,11,40:18
7,12,40:18
7,13,40:18
7,14,40:18
7,15,40:18
7,16,40:18
7,17,40:18
7,18,40:18
7,19,40:18
8,-23,40:18
8,-22,40:18
8,-21,40:18
8,-20,40:18
8,-19,40:18
8,-18,40:18
8,-17,40:18
8,-16,40:18
8,-15,40:18
8,-14,40:18
8,-13,40:18
8,-12,40:18
8,-11,40:18
8,-10,40:18
8,-9,40:18
8,-8,40:18
8,-7,40:18
8,-6,40:18
8,-5,40:18
8,-4,40:18
8,-3,40:18
8,-2,40:18
8,-1,40:18
8,0,40:18
8,1,40:18
8,2,40:18
8,3,40:18
8,4,40:18
8,5,40:18
8,6,40:18
8,7,40:18
8,8,40:18
8,9,40:18
8,10,40:18
8,11,40:18
8,12,40:18
8,13,40:18
8,14,40:18
8,15,40:18
8,16,40:18
8,17,40:18
8,18,40:18
9,-22,40:18
9,-21,40:18
9,-20,40:18
9,-19,40:18
9,-18,40:18
9,-17,40:18
9,-16,40:18
9,-15,40:18
9,-14,40:18
9,-13,40:18
9,-12,40:18
9,-11,40:18
9,-10,40:18
9,-9,40:18
9,-8,40:18
9,-7,40:18
9,-6,40:18
9,-5,40:18
9,-4,40:18
9,-3,40:18
9,-2,40:18
9,-1,40:18
9,0,40:18
9,1,40:18
9,2,40:18
9,3,40:18
9,4,40:18
9,5,40:18
9,6,40:18
9,7,40:18
9,8,40:18
9,9,40:18
9,10,40:18
9,11,40:18
9,12,40:18
9,13,40:18
9,14,40:18
9,15,40:18
9,16,40:18
9,17,40:18
9,18,40:18
10,-22,40:18
10,-21,40:18
10,-20,40:18
10,-19,40:18
10,-18,40:18
10,-17,40:18
10,-16,40:18
10,-15,40:18
10,-14,40:18
10,-13,40:18
10,-12,40:18
10,-11,40:18
10,-10,40:18
10,-9,40:18
10,-8,40:18
10,-7,40:18
10,-6,40:18
10,-5,40:18
10,-4,40:18
10,-3,40:18
10,-2,40:18
10,-1,40:18
10,0,40:18
10,1,40:18
10,2,40:18
10,3,40:18
10,4,40:18
10,5,40:18
10,6,40:18
10,7,40:18
10,8,40:18
10,9,40:18
10,10,40:18
10,11,40:18
10,12,40:18
10,13,40:18
10,14,40:18
10,15,40:18
10,16,40:18
10,17,40:18
10,18,40:18
11,-21,40:18
11,-20,40:18
11,-19,40:18
11,-18,40:18
11,-17,40:18
11,-16,40:18
11,-15,40:18
11,-14,40:18
11,-13,40:18
11,-12,40:18
11,-11,40:18
11,-10,40:18
11,-9,40:18
11,-8,40:18
11,-7,40:18
11,-6,40:18
11,-5,40:18
11,-4,40:18
11,-3,40:18
11,-2,40:18
11,-1,40:18
11,0,40:18
11,1,40:18
11,2,40:18
11,3,40:18
11,4,40:18
11,5,40:18
11,6,40:18
11,7,40:18
11,8,40:18
11,9,40:18
11,10,40:18
11,11,40:18
11,12,40:18
11,13,40:18
11,14,40:18
11,15,40:18
11,16,40:18
11,17,40:18
12,-21,40:18
12,-20,40:18
12,-19,40:18
12,-18,40:18
12,-17,40:18
12,-16,40:18
12,-15,40:18
12,-14,40:18
12,-13,40:18
12,-12,40:18
12,-11,40:18
12,-10,40:18
12,-9,40:18
12,-8,40:18
12,-7,40:18
12,-6,40:18
12,-5,40:18
12,-4,40:18
12,-3,40:18
12,-2,40:18
12,-1,40:18
12,0,40:18
12,1,40:18
12,2,40:18
12,3,40:18
12,4,40:18
12,5,40:18
12,6,40:18
12,7,40:18
12,8,40:18
12,9,40:18
12,10,40:18
12,11,40:18
12,12,40:18
12,13,40:18
12,14,40:18
12,15,40:18
12,16,40:18
12,17,40:18
13,-20,40:18
13,-19,40:18
13,-18,40:18
13,-17,40:18
13,-16,40:18
13,-15,40:18
13,-14,40:18
13,-13,40:18
13,-12,40:18
13,-11,40:18
13,-10,40:18
13,-9,40:18
13,-8,40:18
13,-7,40:18
13,-6,40:18
13,-5,40:18
13,-4,40:18
13,-3,40:18
13,-2,40:18
13,-1,40:18
13,0,40:18
13,1,40:18
13,2,40:18
13,3,40:18
13,4,40:18
13,5,40:18
13,6,40:18
13,7,40:18
13,8,40:18
13,9,40:18
13,10,40:18
13,11,40:18
13,12,40:18
13,13,40:18
13,14,40:18
13,15,40:18
13,16,40:18
14,-20,40:18
14,-19,40:18
14,-18,40:18
14,-17,40:18
14,-16,40:18
14,-15,40:18
14,-14,40:18
14,-13,40:18
14,-12,40:18
14,-11,40:18
14,-10,40:18
14,-9,40:18
14,-8,40:18
14,-7,40:18
14,-6,40:18
14,-5,40:18
14,-4,40:18
14,-3,40:18
14,-2,40:18
14,-1,40:18
14,0,40:18
14,1,40:18
14,2,40:18
14,3,40:18
14,4,40:18
14,5,40:18
14,6,40:18
14,7,40:18
14,8,40:18
14,9,40:18
14,10,40:18
14,11,40:18
14,12,40:18
14,13,40:18
14,14,40:18
14,15,40:18
14,16,40:18
15,-19,40:18
15,-18,40:18
15,-17,40:18
15,-16,40:18
15,-15,40:18
15,-14,40:18
15,-13,40:18
15,-12,40:18
15,-11,40:18
15,-10,40:18
15,-9,40:18
15,-8,40:18
15,-7,40:18
15,-6,40:18
15,-5,40:18
15,-4,40:18
15,-3,40:18
15,-2,40:18
15,-1,40:18
15,0,40:18
15,1,40:18
15,2,40:18
15,3,40:18
15,4,40:18
15,5,40:18
15,6,40:18
15,7,40:18
15,8,40:18
15,9,40:18
15,10,40:18
15,11,40:18
15,12,40:18
15,13,40:18
15,14,40:18
15,15,40:18
16,-19,40:18
16,-18,40:18
16,-17,40:18
16,-16,40:18
16,-15,40:18
16,-14,40:18
16,-13,40:18
16,-12,40:18
16,-11,40:18
16,-10,40:18
16,-9,40:18
16,-8,40:18
16,-7,40:18
16,-6,40:18
16,-5,40:18
16,-4,40:18
16,-3,40:18
16,-2,40:18
16,-1,40:18
16,0,40:18
16,1,40:18
16,2,40:18
16,3,40:18
16,4,40:18
16,5,40:18
16,6,40:18
16,7,40:18
16,8,40:18
16,9,40:18
16,10,40:18
16,11,40:18
16,12,40:18
16,13,40:18
16,14,40:18
17,-18,40:18
17,-17,40:18
17,-16,40:18
17,-15,40:18
17,-14,40:18
17,-13,40:18
17,-12,40:18
17,-11,40:18
17,-10,40:18
17,-9,40:18
17,-8,40:18
17,-7,40:18
17,-6,40:18
17,-5,40:18
17,-4,40:18
17,-3,40:18
17,-2,40:18
17,-1,40:18
17,0,40:18
17,1,40:18
17,2,40:18
17,3,40:18
17,4,40:18
17,5,40:18
17,6,40:18
17,7,40:18
17,8,40:18
17,9,40:18
17,10,40:18
17,11,40:18
17,12,40:18
17,13,40:18
18,-17,40:18
18,-16,40:18
18,-15,40:18
18,-14,40:18
18,-13,40:18
18,-12,40:18
18,-11,40:18
18,-10,40:18
18,-9,40:18
18,-8,40:18
18,-7,40:18
18,-6,40:18
18,-5,40:18
18,-4,40:18
18,-3,40:18
18,-2,40:18
18,-1,40:18
18,0,40:18
18,1,40:18
18,2,40:18
18,3,40:18
18,4,40:18
18,5,40:18
18,6,40:18
18,7,40:18
18,8,40:18
18,9,40:18
18,10,40:18
18,11,40:18
18,12,40:18
18,13,40:18
19,-14,40:18
19,-13,40:18
19,-12,40:18
19,-11,40:18
19,-10,40:18
19,-9,40:18
19,-8,40:18
19,-7,40:18
19,-6,40:18
19,-5,40:18
19,-4,40:18
19,-3,40:18
19,-2,40:18
19,-1,40:18
19,0,40:18
19,1,40:18
19,2,40:18
19,3,40:18
19,4,40:18
19,5,40:18
19,6,40:18
19,7,40:18
19,8,40:18
19,9,40:18
19,10,40:18
19,11,40:18
19,12,40:18
20,-12,40:18
20,-11,40:18
20,-10,40:18
20,-9,40:18
20,-8,40:18
20,-7,40:18
20,-6,40:18
20,-5,40:18
20,-4,40:18
20,-3,40:18
20,-2,40:18
20,-1,40:18
20,0,40:18
20,1,40:18
20,2,40:18
20,3,40:18
20,4,40:18
20,5,40:18
20,6,40:18
20,7,40:18
20,8,40:18
20,9,40:18
20,10,40:18
20,11,40:18
21,-11,40:18
21,-10,40:18
21,-9,40:18
21,-8,40:18
21,-7,40:18
21,-6,40:18
21,-5,40:18
21,-4,40:18
21,-3,40:18
21,-2,40:18
21,-1,40:18
21,0,40:18
21,1,40:18
21,2,40:18
21,3,40:18
21,4,40:18
21,5,40:18
21,6,40:18
21,7,40:18
21,8,40:18
21,9,40:18
21,10,40:18
22,-9,40:18
22,-8,40:18
22,-7,40:18
22,-6,40:18
22,-5,40:18
22,-4,40:18
22,-3,40:18
22,-2,40:18
22,-1,40:18
22,0,40:18
22,1,40:18
22,2,40:18
22,3,40:18
22,4,40:18
22,5,40:18
22,6,40:18
22,7,40:18
22,8,40:18
22,9,40:18
23,-7,40:18
23,-6,40:18
23,-5,40:18
23,-4,40:18
23,-3,40:18
23,-2,40:18
23,-1,40:18
23,0,40:18
23,1,40:18
23,2,40:18
23,3,40:18
23,4,40:18
23,5,40:18
23,6,40:18
23,7,40:18
23,8,40:18
24,-4,40:18
24,-3,40:18
24,-2,40:18
24,-1,40:18
24,0,40:18
24,1,40:18
24,2,40:18
24,3,40:18
24,4,40:18
24,5,40:18
25,-1,40:18
25,0,40:18
25,1,40:18
25,2,40:18
25,3,40:18
-18,-7,41:18
-18,-6,41:18
-18,-5,41:18
-18,-4,41:18
-18,-3,41:18
-18,1,41:18
-18,2,41:18
-17,-10,41:18
-17,-9,41:18
-17,-8,41:18
-17,-7,41:18
-17,-6,41:18
-17,-5,41:18
-17,-4,41:18
-17,-3,41:18
-17,-2,41:18
-17,-1,41:18
-17,0,41:18
-17,1,41:18
-17,2,41:18
-17,3,41:18
-17,4,41:18
-17,6,41:18
-16,-12,41:18
-16,-11,41:18
-16,-10,41:18
-16,-9,41:18
-16,-8,41:18
-16,-7,41:18
-16,-6,41:18
-16,-5,41:18
-16,-4,41:18
-16,-3,41:18
-16,-2,41:18
-16,-1,41:18
-16,0,41:18
-16,1,41:18
-16,2,41:18
-16,3,41:18
-16,4,41:18
-16,5,41:18
-16,6,41:18
-16,7,41:18
-16,8,41:18
-15,-13,41:18
-15,-12,41:18
-15,-11,41:18
-15,-10,41:18
-15,-9,41:18
-15,-8,41:18
-15,-7,41:18
-15,-6,41:18
-15,-5,41:18
-15,-4,41:18
-15,-3,41:18
-15,-2,41:18
-15,-1,41:18
-15,0,41:18
-15,1,41:18
-15,2,41:18
-15,3,41:18
-15,4,41:18
-15,5,41:18
-15,6,41:18
-15,7,41:18
-15,8,41:18
-15,9,41:18
-14,-14,41:18
-14,-13,41:18
-14,-12,41:18
-14,-11,41:18
-14,-10,41:18
-14,-9,41:18
-14,-8,41:18
-14,-7,41:18
-14,-6,41:18
-14,-5,41:18
-14,-4,41:18
-14,-3,41:18
-14,-2,41:18
-14,-1,41:18
-14,0,41:18
-14,1,41:18
-14,2,41:18
-14,3,41:18
-14,4,41:18
-14,5,41:18
-14,6,41:18
-14,7,41:18
-14,8,41:18
-14,9,41:18
-14,10,41:18
-13,-15,41:18
-13,-14,41:18
-13,-13,41:18
-13,-12,41:18
-13,-11,41:18
-13,-10,41:18
-13,-9,41:18
-13,-8,41:18
-13,-7,41:18
-13,-6,41:18
-13,-5,41:18
-13,-4,41:18
-13,-3,41:18
-13,-2,41:18
-13,-1,41:18
-13,0,41:18
-13,1,41:18
-13,2,41:18
-13,3,41:18
-13,4,41:18
-13,5,41:18
-13,6,41:18
-13,7,41:18
-13,8,41:18
-13,9,41:18
-13,10,41:18
-13,11,41:18
-12,-16,41:18
-12,-15,41:18
-12,-14,41:18
-12,-13,41:18
-12,-12,41:18
-12,-11,41:18
-12,-10,41:18
-12,-9,41:18
-12,-8,41:18
-12,-7,41:18
-12,-6,41:18
-12,-5,41:18
-12,-4,41:18
-12,-3,41:18
-12,-2,41:18
-12,-1,41:18
-12,0,41:18
-12,1,41:18
-12,2,41:18
-12,3,41:18
-12,4,41:18
-12,5,41:18
-12,6,41:18
-12,7,41:18
-12,8,41:18
-12,9,41:18
-12,10,41:18
-12,11,41:18
-12,12,41:18
-11,-17,41:18
-11,-16,41:18
-11,-15,41:18
-11,-14,41:18
-11,-13,41:18
-11,-12,41:18
-11,-11,41:18
-11,-10,41:18
-11,-9,41:18
-11,-8,41:18
-11,-7,41:18
-11,-6,41:18
-11,-5,41:18
-11,-4,41:18
-11,-3,41:18
-11,-2,41:18
-11,-1,41:18
-11,0,41:18
-11,1,41:18
-11,2,41:18
-11,3,41:18
-11,4,41:18
-11,5,41:18
-11,6,41:18
-11,7,41:18
-11,8,41:18
-11,9,41:18
-11,10,41:18
-11,11,41:18
-11,12,41:18
-11,13,41:18
-10,-18,41:18
-10,-17,41:18
-10,-16,41:18
-10,-15,41:18
-10,-14,41:18
-10,-13,41:18
-10,-12,41:18
-10,-11,41:18
-10,-10,41:18
-10,-9,41:18
-10,-8,41:18
-10,-7,41:18
-10,-6,41:18
-10,-5,41:18
-10,-4,41:18
-10,-3,41:18
-10,-2,41:18
-10,-1,41:18
-10,0,41:18
-10,1,41:18
-10,2,41:18
-10,3,41:18
-10,4,41:18
-10,5,41:18
-10,6,41:18
-10,7,41:18
-10,8,41:18
-10,9,41:18
-10,10,41:18
-10,11,41:18
-10,12,41:18
-10,13,41:18
-10,14,41:18
-9,-19,41:18
-9,-18,41:18
-9,-17,41:18
-9,-16,41:18
-9,-15,41:18
-9,-14,41:18
-9,-13,41:18
-9,-12,41:18
-9,-11,41:18
-9,-10,41:18
-9,-9,41:18
-9,-8,41:18
-9,-7,41:18
-9,-6,41:18
-9,-5,41:18
-9,-4,41:18
-9,-3,41:18
-9,-2,41:18
-9,-1,41:18
-9,0,41:18
-9,1,41:18
-9,2,41:18
-9,3,41:18
-9,4,41:18
-9,5,41:18
-9,6,41:18
-9,7,41:18
-9,8,41:18
-9,9,41:18
-9,10,41:18
-9,11,41:18
-9,12,41:18
-9,13,41:18
-9,14,41:18
-9,15,41:18
-8,-19,41:18
-8,-18,41:18
-8,-17,41:18
-8,-16,41:18
-8,-15,41:18
-8,-14,41:18
-8,-13,41:18
-8,-12,41:18
-8,-11,41:18
-8,-10,41:18
-8,-9,41:18
-8,-8,41:18
-8,-7,41:18
-8,-6,41:18
-8,-5,41:18
-8,-4,41:18
-8,-3,41:18
-8,-2,41:18
-8,-1,41:18
-8,0,41:18
-8,1,41:18
-8,2,41:18
-8,3,41:18
-8,4,41:18
-8,5,41:18
-8,6,41:18
-8,7,41:18
-8,8,41:18
-8,9,41:18
-8,10,41:18
-8,11,41:18
-8,12,41:18
-8,13,41:18
-8,14,41:18
-8,15,41:18
-7,-20,41:18
-7,-19,41:18
-7,-18,41:18
-7,-17,41:18
-7,-16,41:18
-7,-15,41:18
-7,-14,41:18
-7,-13,41:18
-7,-12,41:18
-7,-11,41:18
-7,-10,41:18
-7,-9,41:18
-7,-8,41:18
-7,-7,41:18
-7,-6,41:18
-7,-5,41:18
-7,-4,41:18
-7,-3,41:18
-7,-2,41:18
-7,-1,41:18
-7,0,41:18
-7,1,41:18
-7,2,41:18
-7,3,41:18
-7,4,41:18
-7,5,41:18
-7,6,41:18
-7,7,41:18
-7,8,41:18
-7,9,41:18
-7,10,41:18
-7,11,41:18
-7,12,41:18
-7,13,41:18
-7,14,41:18
-7,15,41:18
-7,16,41:18
-6,-20,41:18
-6,-19,41:18
-6,-18,41:18
-6,-17,41:18
-6,-16,41:18
-6,-15,41:18
-6,-14,41:18
-6,-13,41:18
-6,-12,41:18
-6,-11,41:18
-6,-10,41:18
-6,-9,41:18
-6,-8,41:18
-6,-7,41:18
-6,-6,41:18
-6,-5,41:18
-6,-4,41:18
-6,-3,41:18
-6,-2,41:18
-6,-1,41:18
-6,0,41:18
-6,1,41:18
-6,2,41:18
-6,3,41:18
-6,4,41:18
-6,5,41:18
-6,6,41:18
-6,7,41:18
-6,8,41:18
-6,9,41:18
-6,10,41:18
-6,11,41:18
-6,12,41:18
-6,13,41:18
-6,14,41:18
-6,15,41:18
-6,16,41:18
-5,-21,41:18
-5,-20,41:18
-5,-19,41:18
-5,-18,41:18
-5,-17,41:18
-5,-16,41:18
-5,-15,41:18
-5,-14,41:18
-5,-13,41:18
-5,-12,41:18
-5,-11,41:18
-5,-10,41:18
-5,-9,41:18
-5,-8,41:18
-5,-7,41:18
-5,-6,41:18
-5,-5,41:18
-5,-4,41:18
-5,-3,41:18
-5,-2,41:18
-5,-1,41:18
-5,0,41:18
-5,1,41:18
-5,2,41:18
-5,3,41:18
-5,4,41:18
-5,5,41:18
-5,6,41:18
-5,7,41:18
-5,8,41:18
-5,9,41:18
-5,10,41:18
-5,11,41:18
-5,12,41:18
-5,13,41:18
-5,14,41:18
-5,15,41:18
-5,16,41:18
-5,17,41:18
-4,-21,41:18
-4,-20,41:18
-4,-19,41:18
-4,-18,41:18
-4,-17,41:18
-4,-16,41:18
-4,-15,41:18
-4,-14,41:18
-4,-13,41:18
-4,-12,41:18
-4,-11,41:18
-4,-10,41:18
-4,-9,41:18
-4,-8,41:18
-4,-7,41:18
-4,-6,41:18
-4,-5,41:18
-4,-4,41:18
-4,-3,41:18
-4,-2,41:18
-4,-1,41:18
-4,0,41:18
-4,1,41:18
-4,2,41:18
-4,3,41:18
-4,4,41:18
-4,5,41:18
-4,6,41:18
-4,7,41:18
-4,8,41:18
-4,9,41:18
-4,10,41:18
-4,11,41:18
-4,12,41:18
-4,13,41:18
-4,14,41:18
-4,15,41:18
-4,16,41:18
-4,17,41:18
-3,-21,41:18
-3,-20,41:18
-3,-19,41:18
-3,-18,41:18
-3,-17,41:18
-3,-16,41:18
-3,-15,41:18
-3,-14,41:18
-3,-13,41:18
-3,-12,41:18
-3,-11,41:18
-3,-10,41:18
-3,-9,41:18
-3,-8,41:18
-3,-7,41:18
-3,-6,41:18
-3,-5,41:18
-3,-4,41:18
-3,-3,41:18
-3,-2,41:18
-3,-1,41:18
-3,0,41:18
-3,1,41:18
-3,2,41:18
-3,3,41:18
-3,4,41:18
-3,5,41:18
-3,6,41:18
-3,7,41:18
-3,8,41:18
-3,9,41:18
-3,10,41:18
-3,11,41:18
-3,12,41:18
-3,13,41:18
-3,14,41:18
-3,15,41:18
-3,16,41:18
-3,17,41:18
-2,-22,41:18
-2,-21,41:18
-2,-20,41:18
-2,-19,41:18
-2,-18,41:18
-2,-17,41:18
-2,-16,41:18
-2,-15,41:18
-2,-14,41:18
-2,-13,41:18
-2,-12,41:18
-2,-11,41:18
-2,-10,41:18
-2,-9,41:18
-2,-8,41:18
-2,-7,41:18
-2,-6,41:18
-2,-5,41:18
-2,-4,41:18
-2,-3,41:18
-2,-2,41:18
-2,-1,41:18
-2,0,41:18
-2,1,41:18
-2,2,41:18
-2,3,41:18
-2,4,41:18
-2,5,41:18
-2,6,41:18
-2,7,41:18
-2,8,41:18
-2,9,41:18
-2,10,41:18
-2,11,41:18
-2,12,41:18
-2,13,41:18
-2,14,41:18
-2,15,41:18
-2,16,41:18
-2,17,41:18
-2,18,41:18
-1,-23,41:18
-1,-22,41:18
-1,-21,41:18
-1,-20,41:18
-1,-19,41:18
-1,-18,41:18
-1,-17,41:18
-1,-16,41:18
-1,-15,41:18
-1,-14,41:18
-1,-13,41:18
-1,-12,41:18
-1,-11,41:18
-1,-10,41:18
-1,-9,41:18
-1,-8,41:18
-1,-7,41:18
-1,-6,41:18
-1,-5,41:18
-1,-4,41:18
-1,-3,41:18
-1,-2,41:18
-1,-1,41:18
-1,0,41:18
-1,1,41:18
-1,2,41:18
-1,3,41:18
-1,4,41:18
-1,5,41:18
-1,6,41:18
-1,7,41:18
-1,8,41:18
-1,9,41:18
-1,10,41:18
-1,11,41:18
-1,12,41:18
-1,13,41:18
-1,14,41:18
-1,15,41:18
-1,16,41:18
-1,17,41:18
-1,18,41:18
-1,19,41:18
0,-24,41:18
0,-23,41:18
0,-22,41:18
0,-21,41:18
0,-20,41:18
0,-19,41:18
0,-18,41:18
0,-17,41:18
0,-16,41:18
0,-15,41:18
0,-14,41:18
0,-13,41:18
0,-12,41:18
0,-11,41:18
0,-10,41:18
0,-9,41:18
0,-8,41:18
0,-7,41:18
0,-6,41:18
0,-5,41:18
0,-4,41:18
0,-3,41:18
0,-2,41:18
0,-1,41:18
0,0,41:18
0,1,41:18
0,2,41:18
0,3,41:18
0,4,41:18
0,5,41:18
0,6,41:18
0,7,41:18
0,8,41:18
0,9,41:18
0,10,41:18
0,11,41:18
0,12,41:18
0,13,41:18
0,14,41:18
0,15,41:18
0,16,41:18
0,17,41:18
0,18,41:18
0,19,41:18
1,-24,41:18
1,-23,41:18
1,-22,41:18
1,-21,41:18
1,-20,41:18
1,-19,41:18
1,-18,41:18
1,-17,41:18
1,-16,41:18
1,-15,41:18
1,-14,41:18
1,-13,41:18
1,-12,41:18
1,-11,41:18
1,-10,41:18
1,-9,41:18
1,-8,41:18
1,-7,41:18
1,-6,41:18
1,-5,41:18
1,-4,41:18
1,-3,41:18
1,-2,41:18
1,-1,41:18
1,0,41:18
1,1,41:18
1,2,41:18
1,3,41:18
1,4,41:18
1,5,41:18
1,6,41:18
1,7,41:18
1,8,41:18
1,9,41:18
1,10,41:18
1,11,41:18
1,12,41:18
1,13,41:18
1,14,41:18
1,15,41:18
1,16,41:18
1,17,41:18
1,18,41:18
1,19,41:18
2,-25,41:18
2,-24,41:18
2,-23,41:18
2,-22,41:18
2,-21,41:18
2,-20,41:18
2,-19,41:18
2,-18,41:18
2,-17,41:18
2,-16,41:18
2,-15,41:18
2,-14,41:18
2,-13,41:18
2,-12,41:18
2,-11,41:18
2,-10,41:18
2,-9,41:18
2,-8,41:18
2,-7,41:18
2,-6,41:18
2,-5,41:18
2,-4,41:18
2,-3,41:18
2,-2,41:18
2,-1,41:18
2,0,41:18
2,1,41:18
2,2,41:18
2,3,41:18
2,4,41:18
2,5,41:18
2,6,41:18
2,7,41:18
2,8,41:18
2,9,41:18
2,10,41:18
2,11,41:18
2,12,41:18
2,13,41:18
2,14,41:18
2,15,41:18
2,16,41:18
2,17,41:18
2,18,41:18
2,19,41:18
3,-25,41:18
3,-24,41:18
3,-23,41:18
3,-22,41:18
3,-21,41:18
3,-20,41:18
3,-19,41:18
3,-18,41:18
3,-17,41:18
3,-16,41:18
3,-15,41:18
3,-14,41:18
3,-13,41:18
3,-12,41:18
3,-11,41:18
3,-10,41:18
3,-9,41:18
3,-8,41:18
3,-7,41:18
3,-6,41:18
3,-5,41:18
3,-4,41:18
3,-3,41:18
3,-2,41:18
3,-1,41:18
3,0,41:18
3,1,41:18
3,2,41:18
3,3,41:18
3,4,41:18
3,5,41:18
3,6,41:18
3,7,41:18
3,8,41:18
3,9,41:18
3,10,41:18
3,11,41:18
3,12,41:18
3,13,41:18
3,14,41:18
3,15,41:18
3,16,41:18
3,17,41:18
3,18,41:18
3,19,41:18
3,20,41:18
4,-25,41:18
4,-24,41:18
4,-23,41:18
4,-22,41:18
4,-21,41:18
4,-20,41:18
4,-19,41:18
4,-18,41:18
4,-17,41:18
4,-16,41:18
4,-15,41:18
4,-14,41:18
4,-13,41:18
4,-12,41:18
4,-11,41:18
4,-10,41:18
4,-9,41:18
4,-8,41:18
4,-7,41:18
4,-6,41:18
4,-5,41:18
4,-4,41:18
4,-3,41:18
4,-2,41:18
4,-1,41:18
4,0,41:18
4,1,41:18
4,2,41:18
4,3,41:18
4,4,41:18
4,5,41:18
4,6,41:18
4,7,41:18
4,8,41:18
4,9,41:18
4,10,41:18
4,11,41:18
4,12,41:18
4,13,41:18
4,14,41:18
4,15,41:18
4,16,41:18
4,17,41:18
4,18,41:18
4,19,41:18
4,20,41:18
5,-25,41:18
5,-24,41:18
5,-23,41:18
5,-22,41:18
5,-21,41:18
5,-20,41:18
5,-19,41:18
5,-18,41:18
5,-17,41:18
5,-16,41:18
5,-15,41:18
5,-14,41:18
5,-13,41:18
5,-12,41:18
5,-11,41:18
5,-10,41:18
5,-9,41:18
5,-8,41:18
5,-7,41:18
5,-6,41:18
5,-5,41:18
5,-4,41:18
5,-3,41:18
5,-2,41:18
5,-1,41:18
5,0,41:18
5,1,41:18
5,2,41:18
5,3,41:18
5,4,41:18
5,5,41:18
5,6,41:18
5,7,41:18
5,8,41:18
5,9,41:18
5,10,41:18
5,11,41:18
5,12,41:18
5,13,41:18
5,14,41:18
5,15,41:18
5,16,41:18
5,17,41:18
5,18,41:18
5,19,41:18
5,20,41:18
6,-24,41:18
6,-23,41:18
6,-22,41:18
6,-21,41:18
6,-20,41:18
6,-19,41:18
6,-18,41:18
6,-17,41:18
6,-16,41:18
6,-15,41:18
6,-14,41:18
6,-13,41:18
6,-12,41:18
6,-11,41:18
6,-10,41:18
6,-9,41:18
6,-8,41:18
6,-7,41:18
6,-6,41:18
6,-5,41:18
6,-4,41:18
6,-3,41:18
6,-2,41:18
6,-1,41:18
6,0,41:18
6,1,41:18
6,2,41:18
6,3,41:18
6,4,41:18
6,5,41:18
6,6,41:18
6,7,41:18
6,8,41:18
6,9,41:18
6,10,41:18
6,11,41:18
6,12,41:18
6,13,41:18
6,14,41:18
6,15,41:18
6,16,41:18
6,17,41:18
6,18,41:18
6,19,41:18
6,20,41:18
7,-24,41:18
7,-23,41:18
7,-22,41:18
7,-21,41:18
7,-20,41:18
7,-19,41:18
7,-18,41:18
7,-17,41:18
7,-16,41:18
7,-15,41:18
7,-14,41:18
7,-13,41:18
7,-12,41:18
7,-11,41:18
7,-10,41:18
7,-9,41:18
7,-8,41:18
7,-7,41:18
7,-6,41:18
7,-5,41:18
7,-4,41:18
7,-3,41:18
7,-2,41:18
7,-1,41:18
7,0,41:18
7,1,41:18
7,2,41:18
7,3,41:18
7,4,41:18
7,5,41:18
7,6,41:18
7,7,41:18
7,8,41:18
7,9,41:18
7,10,41:18
7,11,41:18
7,12,41:18
7,13,41:18
7,14,41:18
7,15,41:18
7,16,41:18
7,17,41:18
7,18,41:18
7,19,41:18
8,-23,41:18
8,-22,41:18
8,-21,41:18
8,-20,41:18
8,-19,41:18
8,-18,41:18
8,-17,41:18
8,-16,41:18
8,-15,41:18
8,-14,41:18
8,-13,41:18
8,-12,41:18
8,-11,41:18
8,-10,41:18
8,-9,41:18
8,-8,41:18
8,-7,41:18
8,-6,41:18
8,-5,41:18
8,-4,41:18
8,-3,41:18
8,-2,41:18
8,-1,41:18
8,0,41:18
8,1,41:18
8,2,41:18
8,3,41:18
8,4,41:18
8,5,41:18
8,6,41:18
8,7,41:18
8,8,41:18
8,9,41:18
8,10,41:18
8,11,41:18
8,12,41:18
8,13,41:18
8,14,41:18
8,15,41:18
8,16,41:18
8,17,41:18
8,18,41:18
9,-22,41:18
9,-21,41:18
9,-20,41:18
9,-19,41:18
9,-18,41:18
9,-17,41:18
9,-16,41:18
9,-15,41:18
9,-14,41:18
9,-13,41:18
9,-12,41:18
9,-11,41:18
9,-10,41:18
9,-9,41:18
9,-8,41:18
9,-7,41:18
9,-6,41:18
9,-5,41:18
9,-4,41:18
9,-3,41:18
9,-2,41:18
9,-1,41:18
9,0,41:18
9,1,41:18
9,2,41:18
9,3,41:18
9,4,41:18
9,5,41:18
9,6,41:18
9,7,41:18
9,8,41:18
9,9,41:18
9,10,41:18
9,11,41:18
9,12,41:18
9,13,41:18
9,14,41:18
9,15,41:18
9,16,41:18
9,17,41:18
9,18,41:18
10,-22,41:18
10,-21,41:18
10,-20,41:18
10,-19,41:18
10,-18,41:18
10,-17,41:18
10,-16,41:18
10,-15,41:18
10,-14,41:18
10,-13,41:18
10,-12,41:18
10,-11,41:18
10,-10,41:18
10,-9,41:18
10,-8,41:18
10,-7,41:18
10,-6,41:18
10,-5,41:18
10,-4,41:18
10,-3,41:18
10,-2,41:18
10,-1,41:18
10,0,41:18
10,1,41:18
10,2,41:18
10,3,41:18
10,4,41:18
10,5,41:18
10,6,41:18
10,7,41:18
10,8,41:18
10,9,41:18
10,10,41:18
10,11,41:18
10,12,41:18
10,13,41:18
10,14,41:18
10,15,41:18
10,16,41:18
10,17,41:18
10,18,41:18
11,-21,41:18
11,-20,41:18
11,-19,41:18
11,-18,41:18
11,-17,41:18
11,-16,41:18
11,-15,41:18
11,-14,41:18
11,-13,41:18
11,-12,41:18
11,-11,41:18
11,-10,41:18
11,-9,41:18
11,-8,41:18
11,-7,41:18
11,-6,41:18
11,-5,41:18
11,-4,41:18
11,-3,41:18
11,-2,41:18
11,-1,41:18
11,0,41:18
11,1,41:18
11,2,41:18
11,3,41:18
11,4,41:18
11,5,41:18
11,6,41:18
11,7,41:18
11,8,41:18
11,9,41:18
11,10,41:18
11,11,41:18
11,12,41:18
11,13,41:18
11,14,41:18
11,15,41:18
11,16,41:18
11,17,41:18
12,-21,41:18
12,-20,41:18
12,-19,41:18
12,-18,41:18
12,-17,41:18
12,-16,41:18
12,-15,41:18
12,-14,41:18
12,-13,41:18
12,-12,41:18
12,-11,41:18
12,-10,41:18
12,-9,41:18
12,-8,41:18
12,-7,41:18
12,-6,41:18
12,-5,41:18
12,-4,41:18
12,-3,41:18
12,-2,41:18
12,-1,41:18
12,0,41:18
12,1,41:18
12,2,41:18
12,3,41:18
12,4,41:18
12,5,41:18
12,6,41:18
12,7,41:18
12,8,41:18
12,9,41:18
12,10,41:18
12,11,41:18
12,12,41:18
12,13,41:18
12,14,41:18
12,15,41:18
12,16,41:18
12,17,41:18
13,-20,41:18
13,-19,41:18
13,-18,41:18
13,-17,41:18
13,-16,41:18
13,-15,41:18
13,-14,41:18
13,-13,41:18
13,-12,41:18
13,-11,41:18
13,-10,41:18
13,-9,41:18
13,-8,41:18
13,-7,41:18
13,-6,41:18
13,-5,41:18
13,-4,41:18
13,-3,41:18
13,-2,41:18
13,-1,41:18
13,0,41:18
13,1,41:18
13,2,41:18
13,3,41:18
13,4,41:18
13,5,41:18
13,6,41:18
13,7,41:18
13,8,41:18
13,9,41:18
13,10,41:18
13,11,41:18
13,12,41:18
13,13,41:18
13,14,41:18
13,15,41:18
13,16,41:18
14,-20,41:18
14,-19,41:18
14,-18,41:18
14,-17,41:18
14,-16,41:18
14,-15,41:18
14,-14,41:18
14,-13,41:18
14,-12,41:18
14,-11,41:18
14,-10,41:18
14,-9,41:18
14,-8,41:18
14,-7,41:18
14,-6,41:18
14,-5,41:18
14,-4,41:18
14,-3,41:18
14,-2,41:18
14,-1,41:18
14,0,41:18
14,1,41:18
14,2,41:18
14,3,41:18
14,4,41:18
14,5,41:18
14,6,41:18
14,7,41:18
14,8,41:18
14,9,41:18
14,10,41:18
14,11,41:18
14,12,41:18
14,13,41:18
14,14,41:18
14,15,41:18
14,16,41:18
15,-19,41:18
15,-18,41:18
15,-17,41:18
15,-16,41:18
15,-15,41:18
15,-14,41:18
15,-13,41:18
15,-12,41:18
15,-11,41:18
15,-10,41:18
15,-9,41:18
15,-8,41:18
15,-7,41:18
15,-6,41:18
15,-5,41:18
15,-4,41:18
15,-3,41:18
15,-2,41:18
15,-1,41:18
15,0,41:18
15,1,41:18
15,2,41:18
15,3,41:18
15,4,41:18
15,5,41:18
15,6,41:18
15,7,41:18
15,8,41:18
15,9,41:18
15,10,41:18
15,11,41:18
15,12,41:18
15,13,41:18
15,14,41:18
15,15,41:18
16,-19,41:18
16,-18,41:18
16,-17,41:18
16,-16,41:18
16,-15,41:18
16,-14,41:18
16,-13,41:18
16,-12,41:18
16,-11,41:18
16,-10,41:18
16,-9,41:18
16,-8,41:18
16,-7,41:18
16,-6,41:18
16,-5,41:18
16,-4,41:18
16,-3,41:18
16,-2,41:18
16,-1,41:18
16,0,41:18
16,1,41:18
16,2,41:18
16,3,41:18
16,4,41:18
16,5,41:18
16,6,41:18
16,7,41:18
16,8,41:18
16,9,41:18
16,10,41:18
16,11,41:18
16,12,41:18
16,13,41:18
16,14,41:18
17,-18,41:18
17,-17,41:18
17,-16,41:18
17,-15,41:18
17,-14,41:18
17,-13,41:18
17,-12,41:18
17,-11,41:18
17,-10,41:18
17,-9,41:18
17,-8,41:18
17,-7,41:18
17,-6,41:18
17,-5,41:18
17,-4,41:18
17,-3,41:18
17,-2,41:18
17,-1,41:18
17,0,41:18
17,1,41:18
17,2,41:18
17,3,41:18
17,4,41:18
17,5,41:18
17,6,41:18
17,7,41:18
17,8,41:18
17,9,41:18
17,10,41:18
17,11,41:18
17,12,41:18
17,13,41:18
18,-17,41:18
18,-16,41:18
18,-15,41:18
18,-14,41:18
18,-13,41:18
18,-12,41:18
18,-11,41:18
18,-10,41:18
18,-9,41:18
18,-8,41:18
18,-7,41:18
18,-6,41:18
18,-5,41:18
18,-4,41:18
18,-3,41:18
18,-2,41:18
18,-1,41:18
18,0,41:18
18,1,41:18
18,2,41:18
18,3,41:18
18,4,41:18
18,5,41:18
18,6,41:18
18,7,41:18
18,8,41:18
18,9,41:18
18,10,41:18
18,11,41:18
18,12,41:18
18,13,41:18
19,-14,41:18
19,-13,41:18
19,-12,41:18
19,-11,41:18
19,-10,41:18
19,-9,41:18
19,-8,41:18
19,-7,41:18
19,-6,41:18
19,-5,41:18
19,-4,41:18
19,-3,41:18
19,-2,41:18
19,-1,41:18
19,0,41:18
19,1,41:18
19,2,41:18
19,3,41:18
19,4,41:18
19,5,41:18
19,6,41:18
19,7,41:18
19,8,41:18
19,9,41:18
19,10,41:18
19,11,41:18
19,12,41:18
20,-12,41:18
20,-11,41:18
20,-10,41:18
20,-9,41:18
20,-8,41:18
20,-7,41:18
20,-6,41:18
20,-5,41:18
20,-4,41:18
20,-3,41:18
20,-2,41:18
20,-1,41:18
20,0,41:18
20,1,41:18
20,2,41:18
20,3,41:18
20,4,41:18
20,5,41:18
20,6,41:18
20,7,41:18
20,8,41:18
20,9,41:18
20,10,41:18
20,11,41:18
21,-11,41:18
21,-10,41:18
21,-9,41:18
21,-8,41:18
21,-7,41:18
21,-6,41:18
21,-5,41:18
21,-4,41:18
21,-3,41:18
21,-2,41:18
21,-1,41:18
21,0,41:18
21,1,41:18
21,2,41:18
21,3,41:18
21,4,41:18
21,5,41:18
21,6,41:18
21,7,41:18
21,8,41:18
21,9,41:18
21,10,41:18
22,-9,41:18
22,-8,41:18
22,-7,41:18
22,-6,41:18
22,-5,41:18
22,-4,41:18
22,-3,41:18
22,-2,41:18
22,-1,41:18
22,0,41:18
22,1,41:18
22,2,41:18
22,3,41:18
22,4,41:18
22,5,41:18
22,6,41:18
22,7,41:18
22,8,41:18
22,9,41:18
23,-7,41:18
23,-6,41:18
23,-5,41:18
23,-4,41:18
23,-3,41:18
23,-2,41:18
23,-1,41:18
23,0,41:18
23,1,41:18
23,2,41:18
23,3,41:18
23,4,41:18
23,5,41:18
23,6,41:18
23,7,41:18
23,8,41:18
24,-4,41:18
24,-3,41:18
24,-2,41:18
24,-1,41:18
24,0,41:18
24,1,41:18
24,2,41:18
24,3,41:18
24,4,41:18
24,5,41:18
25,-1,41:18
25,0,41:18
25,1,41:18
25,2,41:18
25,3,41:18
-14,0,42:18
-14,1,42:18
-14,2,42:18
-13,-2,42:18
-13,-1,42:18
-13,0,42:18
-13,1,42:18
-13,2,42:18
-13,3,42:18
-12,-11,42:18
-12,-10,42:18
-12,-5,42:18
-12,-4,42:18
-12,-3,42:18
-12,-2,42:18
-12,-1,42:18
-12,0,42:18
-12,1,42:18
-12,2,42:18
-12,3,42:18
-11,-12,42:18
-11,-11,42:18
-11,-10,42:18
-11,-9,42:18
-11,-8,42:18
-11,-7,42:18
-11,-6,42:18
-11,-5,42:18
-11,-4,42:18
-11,-3,42:18
-11,-2,42:18
-11,-1,42:18
-11,0,42:18
-11,1,42:18
-11,2,42:18
-11,3,42:18
-11,4,42:18
-10,-13,42:18
-10,-12,42:18
-10,-11,42:18
-10,-10,42:18
-10,-9,42:18
-10,-8,42:18
-10,-7,42:18
-10,-6,42:18
-10,-5,42:18
-10,-4,42:18
-10,-3,42:18
-10,-2,42:18
-10,-1,42:18
-10,0,42:18
-10,1,42:18
-10,2,42:18
-10,3,42:18
-10,4,42:18
-10,5,42:18
-9,-13,42:18
-9,-12,42:18
-9,-11,42:18
-9,-10,42:18
-9,-9,42:18
-9,-8,42:18
-9,-7,42:18
-9,-6,42:18
-9,-5,42:18
-9,-4,42:18
-9,-3,42:18
-9,-2,42:18
-9,-1,42:18
-9,0,42:18
-9,1,42:18
-9,2,42:18
-9,3,42:18
-9,4,42:18
-9,5,42:18
-8,-15,42:18
-8,-14,42:18
-8,-13,42:18
-8,-12,42:18
-8,-11,42:18
-8,-10,42:18
-8,-9,42:18
-8,-8,42:18
-8,-7,42:18
-8,-6,42:18
-8,-5,42:18
-8,-4,42:18
-8,-3,42:18
-8,-2,42:18
-8,-1,42:18
-8,0,42:18
-8,1,42:18
-8,2,42:18
-8,3,42:18
-8,4,42:18
-8,5,42:18
-8,6,42:18
-7,-15,42:18
-7,-14,42:18
-7,-13,42:18
-7,-12,42:18
-7,-11,42:18
-7,-10,42:18
-7,-9,42:18
-7,-8,42:18
-7,-7,42:18
-7,-6,42:18
-7,-5,42:18
-7,-4,42:18
-7,-3,42:18
-7,-2,42:18
-7,-1,42:18
-7,0,42:18
-7,1,42:18
-7,2,42:18
-7,3,42:18
-7,4,42:18
-7,5,42:18
-7,6,42:18
-6,-17,42:18
-6,-16,42:18
-6,-15,42:18
-6,-14,42:18
-6,-13,42:18
-6,-12,42:18
-6,-11,42:18
-6,-10,42:18
-6,-9,42:18
-6,-8,42:18
-6,-7,42:18
-6,-6,42:18
-6,-5,42:18
-6,-4,42:18
-6,-3,42:18
-6,-2,42:18
-6,-1,42:18
-6,0,42:18
-6,1,42:18
-6,2,42:18
-6,3,42:18
-6,4,42:18
-6,5,42:18
-6,6,42:18
-6,7,42:18
-5,-16,42:18
-5,-15,42:18
-5,-14,42:18
-5,-13,42:18
-5,-12,42:18
-5,-11,42:18
-5,-10,42:18
-5,-9,42:18
-5,-8,42:18
-5,-7,42:18
-5,-6,42:18
-5,-5,42:18
-5,-4,42:18
-5,-3,42:18
-5,-2,42:18
-5,-1,42:18
-5,0,42:18
-5,1,42:18
-5,2,42:18
-5,3,42:18
-5,4,42:18
-5,5,42:18
-5,6,42:18
-5,7,42:18
-5,8,42:18
-4,-18,42:18
-4,-17,42:18
-4,-16,42:18
-4,-15,42:18
-4,-14,42:18
-4,-13,42:18
-4,-12,42:18
-4,-11,42:18
-4,-10,42:18
-4,-9,42:18
-4,-8,42:18
-4,-7,42:18
-4,-6,42:18
-4,-5,42:18
-4,-4,42:18
-4,-3,42:18
-4,-2,42:18
-4,-1,42:18
-4,0,42:18
-4,1,42:18
-4,2,42:18
-4,3,42:18
-4,4,42:18
-4,5,42:18
-4,6,42:18
-4,7,42:18
-4,8,42:18
-3,-18,42:18
-3,-17,42:18
-3,-16,42:18
-3,-15,42:18
-3,-14,42:18
-3,-13,42:18
-3,-12,42:18
-3,-11,42:18
-3,-10,42:18
-3,-9,42:18
-3,-8,42:18
-3,-7,42:18
-3,-6,42:18
-3,-5,42:18
-3,-4,42:18
-3,-3,42:18
-3,-2,42:18
-3,-1,42:18
-3,0,42:18
-3,1,42:18
-3,2,42:18
-3,3,42:18
-3,4,42:18
-3,5,42:18
-3,6,42:18
-3,7,42:18
-3,8,42:18
-3,9,42:18
-2,-19,42:18
-2,-18,42:18
-2,-17,42:18
-2,-16,42:18
-2,-15,42:18
-2,-14,42:18
-2,-13,42:18
-2,-12,42:18
-2,-11,42:18
-2,-10,42:18
-2,-9,42:18
-2,-8,42:18
-2,-7,42:18
-2,-6,42:18
-2,-5,42:18
-2,-4,42:18
-2,-3,42:18
-2,-2,42:18
-2,-1,42:18
-2,0,42:18
-2,1,42:18
-2,2,42:18
-2,3,42:18
-2,4,42:18
-2,5,42:18
-2,6,42:18
-2,7,42:18
-2,8,42:18
-2,9,42:18
-1,-19,42:18
-1,-18,42:18
-1,-17,42:18
-1,-16,42:18
-1,-15,42:18
-1,-14,42:18
-1,-13,42:18
-1,-12,42:18
-1,-11,42:18
-1,-10,42:18
-1,-9,42:18
-1,-8,42:18
-1,-7,42:18
-1,-6,42:18
-1,-5,42:18
-1,-4,42:18
-1,-3,42:18
-1,-2,42:18
-1,-1,42:18
-1,0,42:18
-1,1,42:18
-1,2,42:18
-1,3,42:18
-1,4,42:18
-1,5,42:18
-1,6,42:18
-1,7,42:18
-1,8,42:18
-1,9,42:18
-1,10,42:18
-1,11,42:18
0,-19,42:18
0,-18,42:18
0,-17,42:18
0,-16,42:18
0,-15,42:18
0,-14,42:18
0,-13,42:18
0,-12,42:18
0,-11,42:18
0,-10,42:18
0,-9,42:18
0,-8,42:18
0,-7,42:18
0,-6,42:18
0,-5,42:18
0,-4,42:18
0,-3,42:18
0,-2,42:18
0,-1,42:18
0,0,42:18
0,1,42:18
0,2,42:18
0,3,42:18
0,4,42:18
0,5,42:18
0,6,42:18
0,7,42:18
0,8,42:18
0,9,42:18
0,10,42:18
0,11,42:18
1,-20,42:18
1,-19,42:18
1,-18,42:18
1,-17,42:18
1,-16,42:18
1,-15,42:18
1,-14,42:18
1,-13,42:18
1,-12,42:18
1,-11,42:18
1,-10,42:18
1,-9,42:18
1,-8,42:18
1,-7,42:18
1,-6,42:18
1,-5,42:18
1,-4,42:18
1,-3,42:18
1,-2,42:18
1,-1,42:18
1,0,42:18
1,1,42:18
1,2,42:18
1,3,42:18
1,4,42:18
1,5,42:18
1,6,42:18
1,7,42:18
1,8,42:18
1,9,42:18
1,10,42:18
1,11,42:18
1,12,42:18
2,-20,42:18
2,-19,42:18
2,-18,42:18
2,-17,42:18
2,-16,42:18
2,-15,42:18
2,-14,42:18
2,-13,42:18
2,-12,42:18
2,-11,42:18
2,-10,42:18
2,-9,42:18
2,-8,42:18
2,-7,42:18
2,-6,42:18
2,-5,42:18
2,-4,42:18
2,-3,42:18
2,-2,42:18
2,-1,42:18
2,0,42:18
2,1,42:18
2,2,42:18
2,3,42:18
2,4,42:18
2,5,42:18
2,6,42:18
2,7,42:18
2,8,42:18
2,9,42:18
2,10,42:18
2,11,42:18
2,12,42:18
3,-19,42:18
3,-18,42:18
3,-17,42:18
3,-16,42:18
3,-15,42:18
3,-14,42:18
3,-13,42:18
3,-12,42:18
3,-11,42:18
3,-10,42:18
3,-9,42:18
3,-8,42:18
3,-7,42:18
3,-6,42:18
3,-5,42:18
3,-4,42:18
3,-3,42:18
3,-2,42:18
3,-1,42:18
3,0,42:18
3,1,42:18
3,2,42:18
3,3,42:18
3,4,42:18
3,5,42:18
3,6,42:18
3,7,42:18
3,8,42:18
3,9,42:18
3,10,42:18
3,11,42:18
4,-19,42:18
4,-18,42:18
4,-17,42:18
4,-16,42:18
4,-15,42:18
4,-14,42:18
4,-13,42:18
4,-12,42:18
4,-11,42:18
4,-10,42:18
4,-9,42:18
4,-8,42:18
4,-7,42:18
4,-6,42:18
4,-5,42:18
4,-4,42:18
4,-3,42:18
4,-2,42:18
4,-1,42:18
4,0,42:18
4,1,42:18
4,2,42:18
4,3,42:18
4,4,42:18
4,5,42:18
4,6,42:18
4,7,42:18
4,8,42:18
4,9,42:18
4,10,42:18
4,11,42:18
4,12,42:18
5,-18,42:18
5,-17,42:18
5,-16,42:18
5,-15,42:18
5,-14,42:18
5,-13,42:18
5,-12,42:18
5,-11,42:18
5,-10,42:18
5,-9,42:18
5,-8,42:18
5,-7,42:18
5,-6,42:18
5,-5,42:18
5,-4,42:18
5,-3,42:18
5,-2,42:18
5,-1,42:18
5,0,42:18
5,1,42:18
5,2,42:18
5,3,42:18
5,4,42:18
5,5,42:18
5,6,42:18
5,7,42:18
5,8,42:18
5,9,42:18
5,10,42:18
5,11,42:18
6,-17,42:18
6,-16,42:18
6,-15,42:18
6,-14,42:18
6,-13,42:18
6,-12,42:18
6,-11,42:18
6,-10,42:18
6,-9,42:18
6,-8,42:18
6,-7,42:18
6,-6,42:18
6,-5,42:18
6,-4,42:18
6,-3,42:18
6,-2,42:18
6,-1,42:18
6,0,42:18
6,1,42:18
6,2,42:18
6,3,42:18
6,4,42:18
6,5,42:18
6,6,42:18
6,7,42:18
6,8,42:18
6,9,42:18
6,10,42:18
6,11,42:18
7,-16,42:18
7,-15,42:18
7,-14,42:18
7,-13,42:18
7,-12,42:18
7,-11,42:18
7,-10,42:18
7,-9,42:18
7,-8,42:18
7,-7,42:18
7,-6,42:18
7,-5,42:18
7,-4,42:18
7,-3,42:18
7,-2,42:18
7,-1,42:18
7,0,42:18
7,1,42:18
7,2,42:18
7,3,42:18
7,4,42:18
7,5,42:18
7,6,42:18
7,7,42:18
7,8,42:18
7,9,42:18
7,10,42:18
8,-16,42:18
8,-15,42:18
8,-14,42:18
8,-13,42:18
8,-12,42:18
8,-11,42:18
8,-10,42:18
8,-9,42:18
8,-8,42:18
8,-7,42:18
8,-6,42:18
8,-5,42:18
8,-4,42:18
8,-3,42:18
8,-2,42:18
8,-1,42:18
8,0,42:18
8,1,42:18
8,2,42:18
8,3,42:18
8,4,42:18
8,5,42:18
8,6,42:18
8,7,42:18
8,8,42:18
8,9,42:18
8,10,42:18
9,-15,42:18
9,-14,42:18
9,-13,42:18
9,-12,42:18
9,-11,42:18
9,-10,42:18
9,-9,42:18
9,-8,42:18
9,-7,42:18
9,-6,42:18
9,-5,42:18
9,-4,42:18
9,-3,42:18
9,-2,42:18
9,-1,42:18
9,0,42:18
9,1,42:18
9,2,42:18
9,3,42:18
9,4,42:18
9,5,42:18
9,6,42:18
9,7,42:18
9,8,42:18
9,9,42:18
10,-14,42:18
10,-13,42:18
10,-12,42:18
10,-11,42:18
10,-10,42:18
10,-9,42:18
10,-8,42:18
10,-7,42:18
10,-6,42:18
10,-5,42:18
10,-4,42:18
10,-3,42:18
10,-2,42:18
10,-1,42:18
10,0,42:18
10,1,42:18
10,2,42:18
10,3,42:18
10,4,42:18
10,5,42:18
10,6,42:18
10,7,42:18
10,8,42:18
10,9,42:18
11,-12,42:18
11,-11,42:18
11,-10,42:18
11,-9,42:18
11,-8,42:18
11,-7,42:18
11,-6,42:18
11,-5,42:18
11,-4,42:18
11,-3,42:18
11,-2,42:18
11,-1,42:18
11,0,42:18
11,1,42:18
11,2,42:18
11,3,42:18
11,4,42:18
11,5,42:18
11,6,42:18
11,7,42:18
11,8,42:18
12,-12,42:18
12,-11,42:18
12,-10,42:18
12,-9,42:18
12,-8,42:18
12,-7,42:18
12,-6,42:18
12,-5,42:18
12,-4,42:18
12,-3,42:18
12,-2,42:18
12,-1,42:18
12,0,42:18
12,1,42:18
12,2,42:18
12,3,42:18
12,4,42:18
12,5,42:18
12,6,42:18
13,-11,42:18
13,-10,42:18
13,-9,42:18
13,-8,42:18
13,-7,42:18
13,-6,42:18
13,-5,42:18
13,-4,42:18
13,-3,42:18
13,-2,42:18
13,-1,42:18
13,0,42:18
13,1,42:18
13,2,42:18
13,3,42:18
13,4,42:18
13,5,42:18
14,-10,42:18
14,-9,42:18
14,-8,42:18
14,-7,42:18
14,-6,42:18
14,-5,42:18
14,-4,42:18
14,-3,42:18
14,-2,42:18
14,-1,42:18
14,0,42:18
14,1,42:18
14,3,42:18
15,-9,42:18
15,-8,42:18
15,-7,42:18
15,-6,42:18
15,-5,42:18
15,-4,42:18
15,-3,42:18
15,-2,42:18
15,-1,42:18
15,0,42:18
15,1,42:18
16,-8,42:18
16,-7,42:18
16,-6,42:18
16,-5,42:18
16,-4,42:18
16,-3,42:18
16,-1,42:18
17,7,42:18.0
17,8,42:18.0
17,9,42:18.0
16,9,42:18.0
18,8,42:18.0
18,7,42:18.0
20,-2,42:18.0
20,-1,42:18.0
19,-1,42:18.0
19,0,42:18.0
20,0,42:18.0
19,-10,42:18.0
18,-10,42:18.0
19,-11,42:18.0
-16,-6,42:18.0
-16,-5,42:18.0
-15,-5,42:18.0
-15,-6,42:18.0
-13,7,42:18.0
-12,7,42:18.0
-12,8,42:18.0
-8,11,42:18.0
-7,11,42:18.0
-7,12,42:18.0
9,12,42:18.0
10,12,42:18.0
11,12,42:18.0
12,-17,42:18.0
13,-17,42:18.0
13,-18,42:18.0
12,-18,42:18.0
13,-16,42:18.0
19,4,42:18.0
-16,2,42:18.0
-9,-17,42:18.0
-12,-15,42:18.0
-12,-14,42:18.0
3,-22,42:18.0
3,-23,42:18.0
4,-23,42:18.0
4,-22,42:18.0
8,-21,42:18.0
16,-13,42:18.0
-6,-3,43:18.0
-5,-4,43:18.0
-5,-5,43:18.0
-5,-6,43:18.0
-5,-7,43:18.0
-4,-7,43:18.0
-4,-8,43:18.0
-3,-8,43:18.0
-2,-8,43:18.0
-2,-9,43:18.0
-1,-9,43:18.0
-1,-10,43:18.0
0,-10,43:18.0
1,-10,43:18.0
2,-10,43:18.0
3,-10,43:18.0
3,-9,43:18.0
4,-9,43:18.0
5,-9,43:18.0
6,-8,43:18.0
7,-7,43:18.0
8,-7,43:18.0
8,-6,43:18.0
9,-6,43:18.0
9,-5,43:18.0
10,-5,43:18.0
10,-4,43:18.0
9,-4,43:18.0
9,-3,43:18.0
9,-2,43:18.0
9,-1,43:18.0
9,0,43:18.0
9,1,43:18.0
8,2,43:18.0
8,3,43:18.0
8,4,43:18.0
8,5,43:18.0
8,6,43:18.0
7,6,43:18.0
6,6,43:18.0
5,6,43:18.0
4,6,43:18.0
3,6,43:18.0
3,5,43:18.0
2,5,43:18.0
1,5,43:18.0
0,5,43:18.0
0,4,43:18.0
-1,4,43:18.0
-2,4,43:18.0
-2,3,43:18.0
-3,3,43:18.0
-4,3,43:18.0
-4,2,43:18.0
-4,1,43:18.0
-5,0,43:18.0
-5,-1,43:18.0
-5,-2,43:18.0
-5,-3,43:18.0
-4,-3,43:18.0
-4,-4,43:18.0
-3,-4,43:18.0
-3,-5,43:18.0
-3,-6,43:18.0
-2,-6,43:18.0
-2,-7,43:18.0
-1,-7,43:18.0
0,-7,43:18.0
1,-7,43:18.0
2,-7,43:18.0
3,-7,43:18.0
3,-6,43:18.0
4,-6,43:18.0
5,-6,43:18.0
5,-5,43:18.0
6,-5,43:18.0
6,-4,43:18.0
6,-3,43:18.0
5,-3,43:18.0
4,-3,43:18.0
3,-3,43:18.0
2,-3,43:18.0
1,-3,43:18.0
0,-3,43:18.0
-1,-3,43:18.0
-2,-3,43:18.0
-2,-2,43:18.0
-2,-1,43:18.0
-1,-1,43:18.0
0,-1,43:18.0
1,-1,43:18.0
2,-1,43:18.0
3,-1,43:18.0
4,-1,43:18.0
5,-1,43:18.0
5,0,43:18.0
6,0,43:18.0
6,1,43:18.0
6,2,43:18.0
5,2,43:18.0
4,2,43:18.0
4,3,43:18.0
3,3,43:18.0
2,3,43:18.0
2,4,43:18.0
1,4,43:18.0
4,5,43:18.0
5,5,43:18.0
6,5,43:18.0
6,4,43:18.0
7,4,43:18.0
7,3,43:18.0
6,3,43:18.0
7,2,43:18.0
7,1,43:18.0
7,0,43:18.0
8,0,43:18.0
8,-1,43:18.0
8,-2,43:18.0
8,-3,43:18.0
8,-4,43:18.0
7,-4,43:18.0
7,-5,43:18.0
7,-6,43:18.0
6,-6,43:18.0
6,-7,43:18.0
5,-7,43:18.0
5,-8,43:18.0
4,-8,43:18.0
3,-8,43:18.0
2,-8,43:18.0
1,-8,43:18.0
1,-9,43:18.0
0,-9,43:18.0
-1,-8,43:18.0
0,-8,43:18.0
-1,-6,43:18.0
0,-6,43:18.0
1,-6,43:18.0
2,-6,43:18.0
4,-7,43:18.0
4,-5,43:18.0
3,-5,43:18.0
2,-5,43:18.0
1,-5,43:18.0
0,-5,43:18.0
-1,-5,43:18.0
4,-4,43:18.0
3,-4,43:18.0
2,-4,43:18.0
1,-4,43:18.0
0,-4,43:18.0
-1,-4,43:18.0
-2,-4,43:18.0
5,-4,43:18.0
3,-2,43:18.0
2,-2,43:18.0
1,-2,43:18.0
0,-2,43:18.0
-1,-2,43:18.0
4,-2,43:18.0
5,-2,43:18.0
6,-2,43:18.0
6,-1,43:18.0
7,-1,43:18.0
7,-2,43:18.0
8,-5,43:18.0
8,1,43:18.0
7,5,43:18.0
9,4,43:18.0
9,3,43:18.0
4,7,43:18.0
5,7,43:18.0
5,8,43:18.0
0,3,43:18.0
-1,3,43:18.0
-2,2,43:18.0
-3,2,43:18.0
-3,1,43:18.0
-4,0,43:18.0
-4,-1,43:18.0
-4,-2,43:18.0
-6,-2,43:18.0
-6,-1,43:18.0
-5,1,43:18.0
-6,2,43:18.0
-5,2,43:18.0
-6,-4,43:18.0
-7,-4,43:18.0
-7,-5,43:18.0
-7,-6,43:18.0
-7,-7,43:18.0
-6,-7,43:18.0
-5,-8,43:18.0
-4,-5,43:18.0
-4,-6,43:18.0
-3,-7,43:18.0
-6,-6,43:18.0
-2,-5,43:18.0
-1,0,43:18.0
0,0,43:18.0
0,1,43:18.0
1,1,43:18.0
1,2,43:18.0
2,2,43:18.0
2,1,43:18.0
3,1,43:18.0
3,0,43:18.0
2,0,43:18.0
1,0,43:18.0
-2,0,43:18.0
-3,0,43:18.0
-3,-1,43:18.0
-3,-2,43:18.0
-2,1,43:18.0
-1,2,43:18.0
1,3,43:18.0
3,4,43:18.0
4,4,43:18.0
5,4,43:18.0
5,3,43:18.0
5,1,43:18.0
7,-3,43:18.0
2,-9,43:18.0
2,-11,43:18.0
1,-11,43:18.0
4,0,43:18.0
10,0,43:18.0
10,-1,43:18.0
10,-10,43:18.0
10,-11,43:18.0
9,-10,43:18.0
9,-11,43:18.0
12,-4,43:18.0
13,-4,43:18.0
13,-3,43:18.0
12,-3,43:18.0
-7,-12,43:18.0
-7,-11,43:18.0
-6,-11,43:18.0
-6,-12,43:18.0
-10,-3,43:18.0
-10,-2,43:18.0
-11,-2,43:18.0
-9,2,43:18.0
-9,3,43:18.0
-2,6,43:18.0
-1,7,43:18.0
-1,8,43:18.0
0,8,43:18.0
0,9,43:18.0
12,3,43:18.0
12,2,43:18.0
2,-2,44:18.0
1,-2,44:18.0
1,-3,44:18.0
0,-4,44:18.0
0,-5,44:18.0
1,-5,44:18.0
1,-6,44:18.0
2,-6,44:18.0
3,-6,44:18.0
3,-5,44:18.0
4,-5,44:18.0
4,-4,44:18.0
4,-3,44:18.0
3,-3,44:18.0
2,-3,44:18.0
2,-4,44:18.0
2,-5,44:18.0
3,-4,44:18.0
1,-4,44:18.0
7,2,44:18.0
7,3,44:18.0
6,3,44:18.0
6,4,44:18.0
6,5,44:18.0
7,5,44:18.0
7,4,44:18.0
8,3,44:18.0
8,4,44:18.0
8,-4,44:18.0
8,-3,44:18.0
7,-3,44:18.0
7,-4,44:18.0
7,-2,44:18.0
8,-2,44:18.0
-3,-7,44:18.0
-4,-7,44:18.0
-3,-8,44:18.0
-2,-8,44:18.0
-2,-7,44:18.0
-2,-6,44:18.0
-3,-6,44:18.0
-4,-1,44:18.0
-4,0,44:18.0
-3,0,44:18.0
-3,-1,44:18.0
1,3,44:18.0
1,4,44:18.0
2,4,44:18.0
1,-9,44:18.0
2,-10,44:18.0
2,-9,44:18.0
3,-9,44:18.0
9,-10,44:18.0
-6,-11,44:18.0
-10,-2,44:18.0
-1,8,44:18.0
-1,7,44:18.0
12,2,44:18.0
12,-4,44:18.0
12,-3,44:18.0
2,-4,45:0
2,-5,45:0
3,-5,45:0
3,-4,45:0
-3,-7,45:0
2,-10,45:0
8,-3,45:0
7,-3,45:0
7,3,45:0
7,4,45:0
6,4,45:0
1,4,45:0
-4,-1,45:0
-3,-1,45:0
2,-4,46:0
7,-3,46:0
-3,-1,46:0
